Workbook
Name t_1808C6FC6A453E189590B6A8192E4536: 'Dropdown Lists'!$C$1:$C$1
Name t_F79C95F805EE36BBB84C18465D36021B: 'Dropdown Lists'!$C$2:$D$2
Name t_587528E0BC7D39F9B8AA2A1652516805: 'Dropdown Lists'!$C$3:$D$3
Name t_DA4704BE98C838D7A502399A0721568B: 'Dropdown Lists'!$C$4:$G$4
Name t_5064CA6125573355A2FD82E377A0BF7E: 'Dropdown Lists'!$C$5:$H$5
Name t_17E60E5D02BB33F3AF7A3EED5D5415FD: 'Dropdown Lists'!$C$6:$L$6
Name t_736BE9EEE1053213A6B82AD1480B691C: 'Dropdown Lists'!$C$7:$F$7
Name t_858B2FDF179E3924854C6E43A095C451: 'Dropdown Lists'!$C$8:$H$8
Name t_5A99349743543171AD9630656733C934: 'Dropdown Lists'!$C$9:$G$9
Name t_1CD0B95B2F4E3520B8986C5E582BCF41: 'Dropdown Lists'!$C$10:$V$10
Name t_E40EB3C4D044390294BABB6A79763663: 'Dropdown Lists'!$C$11:$K$11
Name t_26BBFCE4984F309F96D1B5F39E50ECFA: 'Dropdown Lists'!$C$12:$F$12
Name t_7EBCC2A0D1B4393DBD3F190522A3A27B: 'Dropdown Lists'!$C$13:$S$13
Name t_3A2961E8A650377C96E858E2A05E89E2: 'Dropdown Lists'!$C$14:$P$14
Name t_44B1910A33BB34DAABA3AA948D1E535A: 'Dropdown Lists'!$C$15:$K$15
Name t_B18FA77C7E1C3C2D96C9B3183723C7AB: 'Dropdown Lists'!$C$16:$E$16
Name t_36FF5E4190DD3B44A36CC8A376702AE5: 'Dropdown Lists'!$C$17:$C$17
Name t_01F852490E3F3B6A9FA03DAB63B0523C: 'Dropdown Lists'!$C$18:$C$18
Name t_546D1C83E9C43F67A9474775343D6D11: 'Dropdown Lists'!$C$19:$J$19
Name t_7BD4ABA6C9F532769A0BB405C6ABCDD2: 'Dropdown Lists'!$C$20:$V$20
Name t_020DDE13325431E1A61E618D0D13D335: 'Dropdown Lists'!$C$21:$HY$21
Name t_15B3E22E95C03167B9243051158B0DB9: 'Dropdown Lists'!$C$22:$F$22
Name t_4658AC3F340835E79FC8783FE4BC085E: 'Dropdown Lists'!$C$23:$F$23
Name t_EE5F1D3FC880345E98D77C96BF4DC860: 'Dropdown Lists'!$C$24:$D$24
Name t_84A592A17FA338EAA65330D57C433496: 'Dropdown Lists'!$C$25:$G$25
Name t_4761821AD7CC3F20835E17536B47EE65: 'Dropdown Lists'!$C$26:$F$26
Name t_4DD4BC44901E3AE5974301256FC27C9C: 'Dropdown Lists'!$C$27:$CO$27
Name t_C4FAFFF5E6F53098A3C6856A600D7AA8: 'Dropdown Lists'!$C$28:$F$28
Name t_E85803111A1E316FA5A34782F86C7BEB: 'Dropdown Lists'!$C$29:$D$29
Name t_7280ED18453C39928F2627DE7455E044: 'Dropdown Lists'!$C$30:$E$30
Name t_95D6A123266B3953ACF82307E72765BA: 'Dropdown Lists'!$C$31:$E$31
Name t_1B9616506B2F365E86F1A4CD85186153: 'Dropdown Lists'!$C$32:$V$32
Name t_FCEC09D6AA5B3B9DA3CE0A080F4F1303: 'Dropdown Lists'!$C$33:$F$33
Name t_9EFB44A0F8BC3076948E69BB8F179FE2: 'Dropdown Lists'!$C$34:$D$34
Name t_ED33C6C2F205356E8B4B96BAEC6E8050: 'Dropdown Lists'!$C$35:$G$35
Name t_9945D74BF90A323590BB7913A6BDAEB1: 'Dropdown Lists'!$C$36:$G$36
Name t_2CDF55C1201B321FB9AFB3936818BB81: 'Dropdown Lists'!$C$37:$E$37
Name t_B062C7406B5F3148961B98F4BCF6C97D: 'Dropdown Lists'!$C$38:$I$38
Name t_2561195BA58039D58C1B00DDC90C51A7: 'Dropdown Lists'!$C$39:$E$39
Name t_F0176CE10EC43216AB15C1F3C04F4DAB: 'Dropdown Lists'!$C$40:$G$40
Name t_3EDD81A3C8CA30859A0A504C5A073E31: 'Dropdown Lists'!$C$41:$G$41
Name t_5AFE6682DEB232C9A413269A28D8393E: 'Dropdown Lists'!$C$42:$G$42
Name t_218B8325ADA03F218A1A9160D962154E: 'Dropdown Lists'!$C$43:$I$43
Name t_3248B74A8328300B800D46E499DE6785: 'Dropdown Lists'!$C$44:$D$44
Name t_E894F00276CF34D0BCECCB16ECC83B67: 'Dropdown Lists'!$C$45:$I$45
Name t_77AEA90B195633379E25495BA6B0BDEC: 'Dropdown Lists'!$C$46:$D$46
Name t_61D5C25AC36736FFA144022833DE1CDC: 'Dropdown Lists'!$C$47:$I$47
Name t_A52C2F9DD9943FA8865D2125B3ABA78D: 'Dropdown Lists'!$C$48:$D$48
Name t_3CD805419C8C34E088F5CF61D72F01A4: 'Dropdown Lists'!$C$49:$I$49
Name t_3053ECF5E13A3964BF63E89108721EA0: 'Dropdown Lists'!$C$50:$C$50
Name t_75C39AEEC34432888438A4C438CC5DBA: 'Dropdown Lists'!$C$51:$D$51
Name t_C4E6136430B83943B13F89962B70311C: 'Dropdown Lists'!$C$52:$HV$52
Name t_4172D1F57599323187CADD780D948A4B: 'Dropdown Lists'!$C$53:$AG$53
Name condition_89D3B1E0A9DA3555B19AC4B84605A88B: 'Conditions List'!$C$1:$C$1
Name condition_E91D7D3AED243B3C9270F77B3B13D394: 'Conditions List'!$C$2:$D$2
Name condition_308E72ECF4B933A6A3C645A8467BC71E: 'Conditions List'!$C$3:$G$3
Name condition_F0BF8E16488432F9B09B186305622CD8: 'Conditions List'!$C$4:$C$4
Name condition_851AB4D926583A659171AB36316BE900: 'Conditions List'!$C$5:$O$5
Name condition_D45499349AFB3761AE10B8529FEA03C2: 'Conditions List'!$C$6:$O$6
Name condition_E36409CE568836BAA4F1A31911103C9D: 'Conditions List'!$C$7:$O$7

Sheet 지침
A1: 템플릿 사용 가이드
A2: 이 페이지를 인쇄하세요
A3: 이 페이지에서는 템플릿 스프레드시트를 생성, 검증 및 Temu에 제출하는 데 필요한 세부 정보를 찾을 수 있습니다. 프로세스 전반에 걸쳐 참조하기 쉽도록 이 페이지를 인쇄하는 것이 좋습니다.
A4: 이 파일의 버전을 Excel 형식으로 하드 드라이브에 저장하세요. 다음으로, 다음 지침을 따라 Template 탭에 제품 정보를 입력하세요.
A6: 이미지 탭
A7: Temu의 시각적 콘텐츠 가이드라인을 숙지하려면 Images 탭을 참조하세요. Temu에 제공하는 이미지가 이러한 지정된 표준에 부합하는지 확인하여 균일성과 우수성을 유지하세요.
A8: 모든 제품에 이미지를 제공하는 것이 중요합니다. 이미지 URL을 제공하여 이미지를 업로드하세요.
A10: 예시 탭
A11: 제품 세부 정보를 입력하는 방법의 샘플을 보려면 예제 탭을 확인하세요. 이것은 단지 귀하의 안내를 위해 제공됩니다. 잘못된 제품 정보가 인벤토리 파일에 통합되는 것을 방지하기 위해 예제 시트에서 직접 귀하의 제품을 편집해서는 안 됩니다.
A13: Template
A14: 이 플랫폼은 제품 정보를 일괄적으로 채우고 Excel 파일을 업로드하여 추가된 제품을 제출할 수 있도록 지원합니다. 공급업체는 내장된 수식 및 코드 로직이 포함된 Excel 템플릿 파일을 사용하여 새 단일 SKU 항목 및 다중 SKU 항목을 직접 만들 수 있습니다.
A15: 1. 권장 소프트웨어: 파일 호환성을 고려하여 Office - Excel을 사용하여 템플릿 파일을 사용 및 편집하는 것이 좋습니다.
... A29: Temu는 때때로 활동 요구 사항, 데이터 유효성 검사 규칙, 설명 텍스트 등을 업데이트합니다. 최신 템플릿이 표시되면 해당 템플릿을 사용해 주세요.

Sheet 이미지
A1: 이미지 표준
A3: Temu의 모든 제품에는 하나 이상의 제품 이미지가 필요합니다. 명확하고, 간단하며, 이해하기 쉬운 이미지를 선택하세요. 이미지를 정확하게 표현하고, 정보가 풍부하고, 매력적으로 표현해야 합니다. 판매 중인 제품만 보여주세요. 가능하면 여러 이미지를 제공하고, 각각 제품의 각도와 세부 정보를 보여주세요. 이것은 고객에게 제품을 보여줄 기회이므로 품질이 중요합니다.
A4: 당사는 이미지 기준에 맞지 않는 이미지를 거부할 권리가 있습니다.
A5: 귀하가 제출한 이미지에 대한 모든 필요한 권리를 보유하는 것은 귀하의 책임입니다.
A7: SKU 이미지
A9: SKU 이미지는 제품 페이지 상단에 표시되며, 다양한 SKU 이미지가 제품의 캐러셀을 구성합니다.
A10: 의류 제품의 경우 업로드하는 이미지는 최대 3MB 크기, 종횡비 3:4, 너비 ≥ 1340px, 높이 ≥ 1785px여야 합니다. 동일한 색상의 SKU는 회전형 이미지 세트를 공유합니다.
A11: 의류가 아닌 제품의 경우 업로드하는 이미지의 최대 크기는 3MB, 종횡비는 1:1, 너비와 높이는 ≥ 800px여야 합니다.
A12: 최대 10개의 이미지를 업로드할 수 있으며, 각 셀에는 이미지 URL이 하나씩 포함됩니다.
A14: 제품 동영상
A16: 제품 동영상은 제품 페이지 상단에 표시됩니다.
A17: 업로드하는 비디오의 최대 크기는 100MB, 길이는 180초를 넘지 않아야 하며, 해상도는 최소 720P여야 합니다.
... A28: 최대 크기 300MB, 길이 180초 이하, 1:1, 4:3 또는 16:9의 가로 세로 비율, 최소 720P 해상도의 동영상을 업로드하세요.

Sheet 예시
A1: 1. 예제 탭의 내용을 검토하는 것 외에도 이 문서에 제공된 지침 탭을 꼼꼼히 읽어보세요.
A2: 2. 제공된 예는 단지 설명일 뿐임을 알아두십시오. 맞춤형 템플릿에 나타나는 열은 선택한 범주에 따라 달라집니다. 템플릿 탭을 사용하여 템플릿 스프레드시트를 생성하십시오.
A3: 3. 일부 선택 열은 더 나은 표현을 위해 축소되었습니다. 해당 열이나 섹션에서 '+' 버튼을 클릭하여 축소된 영역을 표시하세요.
A4: 4. 제품 입력을 제출할 때 발생하는 오류는 처리 결과를 보거나 판매자 지원팀에 문의하여 해결할 수 있습니다.
A5: 일부 필드는 필수입니다. 다른 필드는 선택 사항입니다. | B5: 제품 식별 정보 | K5: 제품 설명 | BP5: 제품 세부 정보 | HK5: 판매 부동산 | IC5: 사이즈 차트 | IV5: 버전 | JP5: 공급 | JT5: 자격
B6: 카테고리 | C6: 제품명 | D6: 아웃굿즈스앤 | E6: 아웃스쿠스앤 | F6: 업데이트 또는 추가 | G6: 제품 ID | H6: SKU ID | I6: 브랜드 | J6: 상표 | K6: 제품 설명 | L6: 글머리 기호 | M6: 글머리 기호 | N6: 글머리 기호 | O6: 글머리 기호 | P6: 글머리 기호 | Q6: 글머리 기호 | R6: 상세 이미지 URL | S6: 상세 이미지 URL | T6: 상세 이미지 URL | U6: 상세 이미지 URL | V6: 상세 이미지 URL | W6: 상세 이미지 URL | X6: 상세 이미지 URL | Y6: 상세 이미지 URL | Z6: 상세 이미지 URL | AA6: 상세 이미지 URL | AB6: 상세 이미지 URL | AC6: 상세 이미지 URL | AD6: 상세 이미지 URL | AE6: 상세 이미지 URL | AF6: 상세 이미지 URL | AG6: 상세 이미지 URL | AH6: 상세 이미지 URL | AI6: 상세 이미지 URL | AJ6: 상세 이미지 URL | AK6: 상세 이미지 URL | AL6: 상세 이미지 URL | AM6: 상세 이미지 URL | AN6: 상세 이미지 URL | AO6: 상세 이미지 URL | AP6: 상세 이미지 URL | AQ6: 상세 이미지 URL | AR6: 상세 이미지 URL | AS6: 상세 이미지 URL | AT6: 상세 이미지 URL | AU6: 상세 이미지 URL | AV6: 상세 이미지 URL | AW6: 상세 이미지 URL | AX6: 상세 이미지 URL | AY6: 상세 이미지 URL | AZ6: 상세 이미지 URL | BA6: 상세 이미지 URL | BB6: 상세 이미지 URL | BC6: 상세 이미지 URL | BD6: 상세 이미지 URL | BE6: 상세 이미지 URL | BF6: 상세 이미지 URL | BG6: 상세 이미지 URL | BH6: 상세 이미지 URL | BI6: 상세 이미지 URL | BJ6: 상세 이미지 URL | BK6: 상세 이미지 URL | BL6: 상세 이미지 URL | BM6: 상세 이미지 URL | BN6: 상세 이미지 URL | BO6: 세부 비디오 URL | BP6: 121 - 재료 | BQ6: 121 - 재료 | BR6: 121 - 재료 | BS6: 121 - 재료 | BT6: 121 - 재료 | BU6: 132 - 마감 유형 | BV6: 210 - 가구 장식 | BW6: 19 - 스타일 | BX6: 1561 - 전력 공급 방식 | BY6: 1132 - 작동 전압 | BZ6: 1485 - 플러그 규격 | CA6: 1485 - 플러그 규격 | CB6: 1485 - 플러그 규격 | CC6: 1571 - 허용 가능한 전압 범위 | CD6: 4102 - 우드 소재 함유 여부 | CE6: 4097 - 나무 종류 | CF6: 4097 - 나무 종류 | CG6: 12 - 소재 | CH6: 4098 - 재료 형성 방식 | CI6: 4098 - 재료 형성 방식 | CJ6: 4098 - 재료 형성 방식 | CK6: 4099 - 섬유판 밀도 | CL6: 6171 - 독립 여부 | CM6: 6172 - 폐쇄형수납용량 | CN6: 6173 - 조립 후 높이 | CO6: 6174 - 무게 | CP6: 2153 - 배터리 속성 | CQ6: 2147 - 충전식 배터리 | CR6: 2154 - 태양 전지 | CS6: 3740 - 비충전 전지 | CT6: 2028 - 배터리 용량(mAh) - value | CU6: 2028 - 배터리 용량(mAh) - unit | CV6: 63 - 색상 | CW6: 6495 - 조립 여부 | CX6: 7096 - SKU별 조립된 부품 수 | CY6: 15 - 성분:나일론 | CZ6: 15 - 성분:폴리에스테르 | DA6: 15 - 성분:폴리아미드 | DB6: 15 - 성분:엘라스테인 | DC6: 15 - 성분:스판덱스 | DD6: 15 - 성분:아크릴 | DE6: 15 - 성분:면 | DF6: 15 - 성분:실크 | DG6: 15 - 성분:린넨 | DH6: 15 - 성분:모달 | DI6: 15 - 성분:비스코스 | DJ6: 15 - 성분:레이온 | DK6: 15 - 성분:탄소 | DL6: 15 - 성분:금속 | DM6: 15 - 성분:양모 | DN6: 15 - 성분:캐시미어 천 | DO6: 15 - 성분:모헤어 | DP6: 15 - 성분:토끼 털 | DQ6: 15 - 성분:소가죽 | DR6: 15 - 성분:양가죽 | DS6: 15 - 성분:돼지가죽 | DT6: 15 - 성분:폴리우레탄 | DU6: 15 - 성분:폴리염화비닐 | DV6: 15 - 성분:큐프로 | DW6: 15 - 성분:리오셀 | DX6: 15 - 성분:아세테이트 | DY6: 15 - 성분:아래에 | DZ6: 15 - 성분:깃털 | EA6: 15 - 성분:덕 다운 | EB6: 15 - 성분:알파카 | EC6: 15 - 성분:금속화 섬유 | ED6: 15 - 성분:폴리프로필렌 섬유 | EE6: 15 - 성분:기타 섬유 | EF6: 15 - 성분:라미 | EG6: 28 - 길이 | EH6: 74 - 벨트 | EI6: 29 - 소매 길이 | EJ6: 27 - 소매 유형 | EK6: 94 - 가슴 패드 | EL6: 83 - 세부 사항 | EM6: 26 - 무늬 | EN6: 24 - 투명성 여부 | EO6: 22 - 옷감 | EP6: 86 - 플래킷 유형 | EQ6: 113 - 윤곽 | ER6: 76 - 계절 | ES6: 20 - 관리 설명 | ET6: 114 - 착용 유형 | EU6: 1352 - 원단 탄력성 | EV6: 1919 - 인화 유형 | EW6: 2103 - 스타일 공급원 | EX6: 1192 - 직조 방법 | EY6: 21 - 옷깃의 모양 | EZ6: 6227 - 수집 | FA6: 6926 - 패브릭 질감 1 | FB6: 6927 - 패브릭 텍스처 2 | FC6: 6928 - 라이닝 텍스처 | FD6: 6930 - 원단 무게 1 (g/m²) - value | FE6: 6930 - 원단 무게 1 (g/m²) - unit | FF6: 6931 - 원단 무게 2 (g/m²) - value | FG6: 6931 - 원단 무게 2 (g/m²) - unit | FH6: 6934 - 라이닝 무게 (g/m²) - value | FI6: 6934 - 라이닝 무게 (g/m²) - unit | FJ6: 6547 - 라이닝 재료:실크 | FK6: 6547 - 라이닝 재료:린넨 | FL6: 6547 - 라이닝 재료:모달 | FM6: 6547 - 라이닝 재료:비스코스 | FN6: 6547 - 라이닝 재료:레이온 | FO6: 6547 - 라이닝 재료:탄소 | FP6: 6547 - 라이닝 재료:금속 | FQ6: 6547 - 라이닝 재료:양모 | FR6: 6547 - 라이닝 재료:캐시미어 천 | FS6: 6547 - 라이닝 재료:모헤어 | FT6: 6547 - 라이닝 재료:토끼 털 | FU6: 6547 - 라이닝 재료:소가죽 | FV6: 6547 - 라이닝 재료:양가죽 | FW6: 6547 - 라이닝 재료:돼지가죽 | FX6: 6547 - 라이닝 재료:폴리우레탄 | FY6: 6547 - 라이닝 재료:폴리염화비닐 | FZ6: 6547 - 라이닝 재료:큐프로 | GA6: 6547 - 라이닝 재료:리오셀 | GB6: 6547 - 라이닝 재료:아세테이트 | GC6: 6547 - 라이닝 재료:아래에 | GD6: 6547 - 라이닝 재료:깃털 | GE6: 6547 - 라이닝 재료:덕 다운 | GF6: 6547 - 라이닝 재료:알파카 | GG6: 6547 - 라이닝 재료:기타 섬유 | GH6: 6547 - 라이닝 재료:폴리에스테르 | GI6: 6547 - 라이닝 재료:금속화 섬유 | GJ6: 6547 - 라이닝 재료:폴리프로필렌 섬유 | GK6: 6547 - 라이닝 재료:라미 | GL6: 6547 - 라이닝 재료:나일론 | GM6: 6547 - 라이닝 재료:폴리아미드 | GN6: 6547 - 라이닝 재료:엘라스테인 | GO6: 6547 - 라이닝 재료:스판덱스 | GP6: 6547 - 라이닝 재료:아크릴 | GQ6: 6547 - 라이닝 재료:면 | GR6: 4134 - 발행자 | GS6: 4130 - 원산지/지역 | GT6: 4137 - 작가 | GU6: 1120 - 설정 여부 | GV6: 4133 - 체재 | GW6: 4123 - 언어 | GX6: 4123 - 언어 | GY6: 4123 - 언어 | GZ6: 4122 - 발행일 | HA6: 4124 - 페이지 수(페이지) - value | HB6: 4124 - 페이지 수(페이지) - unit | HC6: 4131 - 단어 수(10,000 단어) | HD6: 4127 - 제품 중량(g) - value | HE6: 4127 - 제품 중량(g) - unit | HF6: 4128 - 최대 독서 연령(세) - value | HG6: 4128 - 최대 독서 연령(세) - unit | HH6: 4129 - 최소 독서 연령(세) - value | HI6: 4129 - 최소 독서 연령(세) - unit | HJ6: 6855 - 책 제목 | HK6: 변형 테마 | HL6: 사이즈 가족 | HM6: 하위 크기 가족 | HN6: 사이즈 | HO6: 색상 | HP6: 색상 | HQ6: 크기 | HR6: 스타일 | HS6: 재료 | HT6: 풍미 | HU6: 해당하는 사람들 | HV6: 용량 | HW6: 구성 | HX6: 무게 | HY6: 항목 | HZ6: 수량 | IA6: 모델 | IB6: 머리 길이 | IC6: 단위 | ID6: KO 크기 | IE6: 5 - 상의 - Product - 어깨 | IF6: 5 - 상의 - Product - 가슴둘레 | IG6: 5 - 상의 - Product - 길이 | IH6: 5 - 상의 - Product - 소매 길이 | II6: 5 - 상의 - Product - 허리 | IJ6: 5 - 상의 - Product - 밑가슴 둘레 | IK6: 5 - 상의 - Product - 옷깃 둘레 | IL6: 5 - 상의 - Product - 밑단 둘레 | IM6: 5 - 상의 - Product - 팔목 둘레 | IN6: 5 - 상의 - Body - 윗가슴둘레 - min | IO6: 5 - 상의 - Body - 윗가슴둘레 - max | IP6: 5 - 상의 - Body - 허리 - min | IQ6: 5 - 상의 - Body - 허리 - max | IR6: 5 - 상의 - Body - 엉덩이 - min | IS6: 5 - 상의 - Body - 엉덩이 - max | IT6: 5 - 상의 - Body - 키 - min | IU6: 5 - 상의 - Body - 키 - max | IV6: SKU 이미지 URL | IW6: SKU 이미지 URL | IX6: SKU 이미지 URL | IY6: SKU 이미지 URL | IZ6: SKU 이미지 URL | JA6: SKU 이미지 URL | JB6: SKU 이미지 URL | JC6: SKU 이미지 URL | JD6: SKU 이미지 URL | JE6: SKU 이미지 URL | JF6: 수량 | JG6: 기본 가격 - KRW | JH6: 참고 링크: | JI6: 정가 - KRW | JJ6: 무게 - g | JK6: 길이 - cm | JL6: 너비 - cm | JM6: 높이 - cm | JN6: 외부 제품 ID 유형 | JO6: 외부 제품 ID | JP6: 처리 시간 | JQ6: 배송 템플릿 | JR6: 주문 처리 채널 | JS6: 상품 세금 코드(ITC) | JT6: 원산지 | JU6: 출신 지역 | JV6: 제품 가이드 - English
A7: 예시 1: 이것은 새로운 목록을 제공하는 예입니다. 이 예는 변형이 없으며 단일 세부 정보 페이지로 나열됩니다. | B7: 29069 | C7: 예시 여성 티셔츠, 156 블랙 티셔츠 | D7: EXAMPLE-156-US-Black-one-size | E7: EXAMPLE-156-US-Black-one-size | K7: 클래식 핏 티셔츠로 개성을 표현하세요. 100% 코튼으로 제작되어 탁월한 편안함과 내구성을 제공합니다. 티셔츠는 모던한 세련미를 구현한 독특하고 눈길을 끄는 그래픽이 특징입니다. 캐주얼한 외출이나 재킷 아래에 겹쳐 입기에 적합한 이 티셔츠는 모든 경우에 다재다능합니다. 형태를 유지하는 통기성 원단으로, 항상 필요한 옷장 필수품입니다. 자신을 표현하도록 디자인된 셔츠로 개성을 표현하고 편안함을 유지하세요. (문자 수: 493) | L7: 궁극의 편안함을 위한 100% 프리미엄 코튼. | M7: 시대를 초월한 디자인과 모던한 스타일이 만났습니다. | N7: 내구성 있는 원단으로 매일 입기에 완벽합니다. | O7: 세탁기로 세탁 가능하고 관리하기 쉽습니다. | P7: 모든 체형에 다재다능하게 맞습니다. | R7: http://www.companyname.com/images/1250.main.jpg | BW7: Y2K | CG7: 반짝임 | CY7: 35 | CZ7: 55 | DA7: 10 | EG7: 짧은 길이 | EH7: 예 | EI7: 민소매 | EJ7: 래글런 슬리브 | EK7: 아니요 | EL7: 가짜 버튼 | EM7: 버섯 | EN7: 예 | EO7: 신축성 없음 | EP7: 하프 플래킷 | EQ7: A | ER7: 봄/가을 | ES7: 손세탁 또는 전문 드라이클리닝 | ET7: 마른 | EU7: 신축성 없음 | EV7: 프린팅 없음 | EW7: 구매자가 제공 | EX7: 우븐 | EY7: 오프 숄더 | EZ7: 라틴 아메리카 | FA7: 스웨이드/PU | FB7: 스웨이드/PU | FC7: 안감 없음 | FD7: 200 | FE7: g/㎡ | FF7: 300 | FG7: g/㎡ | FH7: 250 | FI7: g/㎡ | HK7: 사이즈 × 색상 | HL7: 10000 - 미국/유럽 사이즈 | HM7: 1 - 단일 사이즈 | HN7: 프리사이즈 | HO7: 하얀색 | IC7: cm-g-ml | ID7: one-size | IF7: 36 | IG7: 28 | IN7: 33.9 | IO7: 35.5 | IP7: 26 | IQ7: 27.6 | IR7: 35.9 | IS7: 37.4 | IV7: http://www.companyname.com/images/1250.main.jpg | JF7: 5 | JG7: 2.99 | JJ7: 9.2 | JK7: 2 | JL7: 3 | JM7: 4 | JP7: 1일 | JQ7: kr1 | JR7: 해당 상품을 직접 발송하겠습니다 | JT7: Republic of Korea
B8: 12408 | C8: 예시 재활용 캐비닛 솔리드 우드, 서랍 4개 | D8: EXAMPLE-576-Brown | E8: EXAMPLE-576-Brown | BP8: 목재 | BU8: 칠한 | BV8: 체리 | BW8: 빈티지 | BX8: 플러그 전원 | BY8: 110V/220V | BZ8: 유럽 ​​표준 플러그 | CD8: 예 | CE8: 견목 | CG8: 실크 | CH8: 기타 | CL8: 예 | CM8: <3.2 입방피트 | CN8: ≥27인치 | CO8: ≥30파운드 | CP8: 비충전식 배터리 | CS8: AAA 배터리 | CU8: 마 | CV8: 빨간색 | CW8: 예 | CX8: ≥5 | HK8: 색상 × 수량 | HP8: 빨간색 | HZ8: 32pcs | IV8: http://www.companyname.com/images/1250.main.jpg | JF8: 0 | JG8: 2.99 | JJ8: 9.2 | JK8: 2 | JL8: 3 | JM8: 4 | JP8: 1일 | JQ8: kr1 | JR8: 해당 상품을 직접 발송하겠습니다 | JT8: Republic of Korea
B9: 48461 | C9: 예시 kr용 책, isbn 포함 | D9: EXAMPLEISBN9787040205190 | E9: EXAMPLEISBN9787040205190 | GR9: 예시 게시자 | GS9: 대한민국 | GT9: 예시 작성자 | GU9: 아니요 | GV9: 하드 커버 | GW9: 영어 | GZ9: 44897 | HA9: 300 | HB9: 페이지 | HC9: 1000 | HD9: 200 | HE9: g | HF9: 99 | HG9: 살이에요 | HH9: 1 | HI9: 살이에요 | HK9: 항목 | IV9: http://www.companyname.com/images/1250.main.jpg | JF9: 20 | JG9: 7.82 | JJ9: 9.2 | JK9: 2 | JL9: 3 | JM9: 4 | JN9: ISBN | JO9: 920000021 | JP9: 1일 | JQ9: kr1 | JR9: 해당 상품을 직접 발송하겠습니다 | JT9: Republic of Korea
E10: 0 | JV10: 0
A11: 예시 2: 이것은 3개의 변형이 있는 1개의 변형 테마(예: 크기)가 있는 제품의 예입니다. 이는 "부모" 상품의 3개의 "자식" SKU입니다. 참고: 제품 이름, 제품 설명, 제품 세부 정보, 오퍼, 자격과 같은 제품 수준 정보의 경우 각 줄이 올바르게 작성되었는지, 정보가 일관되게 입력되었는지 확인하십시오. | B11: 29069 | C11: 예시 여성 티셔츠, 156 블랙 티셔츠 | D11: EXAMPLE-156-US-Black | E11: EXAMPLE-156-US-Black-S | K11: 클래식 핏 티셔츠로 개성을 표현하세요. 100% 코튼으로 제작되어 탁월한 편안함과 내구성을 제공합니다. 티셔츠는 모던한 세련미를 구현한 독특하고 눈길을 끄는 그래픽이 특징입니다. 캐주얼한 외출이나 재킷 아래에 겹쳐 입기에 적합한 이 티셔츠는 모든 경우에 다재다능합니다. 형태를 유지하는 통기성 원단으로, 항상 필요한 옷장 필수품입니다. 자신을 표현하도록 디자인된 셔츠로 개성을 표현하고 편안함을 유지하세요. (문자 수: 493) | L11: 궁극의 편안함을 위한 100% 프리미엄 코튼. | M11: 시대를 초월한 디자인과 모던한 스타일이 만났습니다. | N11: 내구성 있는 원단으로 매일 입기에 완벽합니다. | O11: 세탁기로 세탁 가능하고 관리하기 쉽습니다. | P11: 모든 체형에 다재다능하게 맞습니다. | R11: http://www.companyname.com/images/1250.main.jpg | BW11: Y2K | CG11: 반짝임 | CY11: 35 | CZ11: 55 | DA11: 10 | EG11: 짧은 길이 | EH11: 예 | EI11: 민소매 | EJ11: 래글런 슬리브 | EK11: 아니요 | EL11: 가짜 버튼 | EM11: 버섯 | EN11: 예 | EO11: 신축성 없음 | EP11: 하프 플래킷 | EQ11: A | ER11: 봄/가을 | ES11: 손세탁 또는 전문 드라이클리닝 | ET11: 마른 | EU11: 신축성 없음 | EV11: 프린팅 없음 | EW11: 구매자가 제공 | EX11: 우븐 | EY11: 오프 숄더 | EZ11: 라틴 아메리카 | FA11: 스웨이드/PU | FB11: 스웨이드/PU | FC11: 안감 없음 | FD11: 200 | FE11: g/㎡ | FF11: 300 | FG11: g/㎡ | FH11: 250 | FI11: g/㎡ | HK11: 사이즈 × 색상 | HL11: 10000 - 미국/유럽 사이즈 | HM11: 10 - 알파 | HN11: S | HO11: 하얀색 | IC11: cm-g-ml | ID11: 0 | IF11: 36 | IG11: 28 | IN11: 33.9 | IO11: 35.5 | IP11: 26 | IQ11: 27.6 | IR11: 35.9 | IS11: 37.4 | IV11: http://www.companyname.com/images/1250.main.jpg | JF11: 5 | JG11: 2.99 | JJ11: 9.2 | JK11: 2 | JL11: 3 | JM11: 4 | JP11: 1일 | JQ11: kr1 | JR11: 해당 상품을 직접 발송하겠습니다 | JT11: Republic of Korea
B12: 29069 | C12: 예시 여성 티셔츠, 156 블랙 티셔츠 | D12: EXAMPLE-156-US-Black | E12: EXAMPLE-156-US-Black-M | K12: 클래식 핏 티셔츠로 개성을 표현하세요. 100% 코튼으로 제작되어 탁월한 편안함과 내구성을 제공합니다. 티셔츠는 모던한 세련미를 구현한 독특하고 눈길을 끄는 그래픽이 특징입니다. 캐주얼한 외출이나 재킷 아래에 겹쳐 입기에 적합한 이 티셔츠는 모든 경우에 다재다능합니다. 형태를 유지하는 통기성 원단으로, 항상 필요한 옷장 필수품입니다. 자신을 표현하도록 디자인된 셔츠로 개성을 표현하고 편안함을 유지하세요. (문자 수: 493) | L12: 궁극의 편안함을 위한 100% 프리미엄 코튼. | M12: 시대를 초월한 디자인과 모던한 스타일이 만났습니다. | N12: 내구성 있는 원단으로 매일 입기에 완벽합니다. | O12: 세탁기로 세탁 가능하고 관리하기 쉽습니다. | P12: 모든 체형에 다재다능하게 맞습니다. | R12: http://www.companyname.com/images/1250.main.jpg | BW12: Y2K | CG12: 반짝임 | CY12: 35 | CZ12: 55 | DA12: 10 | EG12: 짧은 길이 | EH12: 예 | EI12: 민소매 | EJ12: 래글런 슬리브 | EK12: 아니요 | EL12: 가짜 버튼 | EM12: 버섯 | EN12: 예 | EO12: 신축성 없음 | EP12: 하프 플래킷 | EQ12: A | ER12: 봄/가을 | ES12: 손세탁 또는 전문 드라이클리닝 | ET12: 마른 | EU12: 신축성 없음 | EV12: 프린팅 없음 | EW12: 구매자가 제공 | EX12: 우븐 | EY12: 오프 숄더 | EZ12: 라틴 아메리카 | FA12: 스웨이드/PU | FB12: 스웨이드/PU | FC12: 안감 없음 | FD12: 200 | FE12: g/㎡ | FF12: 300 | FG12: g/㎡ | FH12: 250 | FI12: g/㎡ | HK12: 사이즈 × 색상 | HL12: 10000 - 미국/유럽 사이즈 | HM12: 10 - 알파 | HN12: M | HO12: 하얀색 | IC12: cm-g-ml | ID12: 2 | IF12: 40 | IG12: 29 | IN12: 35.5 | IO12: 37 | IP12: 27.6 | IQ12: 29.2 | IR12: 27.4 | IS12: 39 | IV12: http://www.companyname.com/images/1250.main.jpg | JF12: 5 | JG12: 2.99 | JJ12: 9.2 | JK12: 2 | JL12: 3 | JM12: 4 | JP12: 1일 | JQ12: kr1 | JR12: 해당 상품을 직접 발송하겠습니다 | JT12: Republic of Korea
B13: 29069 | C13: 예시 여성 티셔츠, 156 블랙 티셔츠 | D13: EXAMPLE-156-US-Black | E13: EXAMPLE-156-US-Black-L | K13: 클래식 핏 티셔츠로 개성을 표현하세요. 100% 코튼으로 제작되어 탁월한 편안함과 내구성을 제공합니다. 티셔츠는 모던한 세련미를 구현한 독특하고 눈길을 끄는 그래픽이 특징입니다. 캐주얼한 외출이나 재킷 아래에 겹쳐 입기에 적합한 이 티셔츠는 모든 경우에 다재다능합니다. 형태를 유지하는 통기성 원단으로, 항상 필요한 옷장 필수품입니다. 자신을 표현하도록 디자인된 셔츠로 개성을 표현하고 편안함을 유지하세요. (문자 수: 493) | L13: 궁극의 편안함을 위한 100% 프리미엄 코튼. | M13: 시대를 초월한 디자인과 모던한 스타일이 만났습니다. | N13: 내구성 있는 원단으로 매일 입기에 완벽합니다. | O13: 세탁기로 세탁 가능하고 관리하기 쉽습니다. | P13: 모든 체형에 다재다능하게 맞습니다. | R13: http://www.companyname.com/images/1250.main.jpg | BW13: Y2K | CG13: 반짝임 | CY13: 35 | CZ13: 55 | DA13: 10 | EG13: 짧은 길이 | EH13: 예 | EI13: 민소매 | EJ13: 래글런 슬리브 | EK13: 아니요 | EL13: 가짜 버튼 | EM13: 버섯 | EN13: 예 | EO13: 신축성 없음 | EP13: 하프 플래킷 | EQ13: A | ER13: 봄/가을 | ES13: 손세탁 또는 전문 드라이클리닝 | ET13: 마른 | EU13: 신축성 없음 | EV13: 프린팅 없음 | EW13: 구매자가 제공 | EX13: 우븐 | EY13: 오프 숄더 | EZ13: 라틴 아메리카 | FA13: 스웨이드/PU | FB13: 스웨이드/PU | FC13: 안감 없음 | FD13: 200 | FE13: g/㎡ | FF13: 300 | FG13: g/㎡ | FH13: 250 | FI13: g/㎡ | HK13: 사이즈 × 색상 | HL13: 10000 - 미국/유럽 사이즈 | HM13: 10 - 알파 | HN13: L | HO13: 하얀색 | IC13: cm-g-ml | ID13: 4 | IF13: 44 | IG13: 30 | IN13: 37.4 | IO13: 39.8 | IP13: 29.6 | IQ13: 31.9 | IR13: 39.4 | IS13: 41.8 | IV13: http://www.companyname.com/images/1250.main.jpg | JF13: 5 | JG13: 2.99 | JJ13: 9.2 | JK13: 2 | JL13: 3 | JM13: 4 | JP13: 1일 | JQ13: kr1 | JR13: 해당 상품을 직접 발송하겠습니다 | JT13: Republic of Korea
B14: 12408 | C14: 예시 재활용 캐비닛 솔리드 우드, 서랍 4개 | D14: EXAMPLE-576 | E14: EXAMPLE-576-Brown | BP14: 목재 | BU14: 칠한 | BV14: 체리 | BW14: 빈티지 | BX14: 플러그 전원 | BY14: 110V/220V | BZ14: 유럽 ​​표준 플러그 | CD14: 예 | CE14: 견목 | CG14: 실크 | CH14: 기타 | CL14: 예 | CM14: <3.2 입방피트 | CN14: ≥27인치 | CO14: ≥30파운드 | CP14: 비충전식 배터리 | CS14: AAA 배터리 | CU14: 마 | CV14: 빨간색 | CW14: 예 | CX14: ≥5 | HK14: 색상 | HP14: 갈색 | IV14: http://www.companyname.com/images/1250.main.jpg | JF14: 5 | JG14: 2.99 | JJ14: 9.2 | JK14: 2 | JL14: 3 | JM14: 4 | JP14: 1일 | JQ14: kr1 | JR14: 해당 상품을 직접 발송하겠습니다 | JT14: Republic of Korea
B15: 12408 | C15: 예시 재활용 캐비닛 솔리드 우드, 서랍 4개 | D15: EXAMPLE-576 | E15: EXAMPLE-576-white | BP15: 목재 | BU15: 칠한 | BV15: 체리 | BW15: 빈티지 | BX15: 플러그 전원 | BY15: 110V/220V | BZ15: 유럽 ​​표준 플러그 | CD15: 예 | CE15: 견목 | CG15: 실크 | CH15: 기타 | CL15: 예 | CM15: <3.2 입방피트 | CN15: ≥27인치 | CO15: ≥30파운드 | CP15: 비충전식 배터리 | CS15: AAA 배터리 | CU15: 마 | CV15: 빨간색 | CW15: 예 | CX15: ≥5 | HK15: 색상 | HP15: 흰색 | IV15: http://www.companyname.com/images/1250.main.jpg | JF15: 5 | JG15: 2.99 | JJ15: 9.2 | JK15: 2 | JL15: 3 | JM15: 4 | JP15: 1일 | JQ15: kr1 | JR15: 해당 상품을 직접 발송하겠습니다 | JT15: Republic of Korea
B16: 12408 | C16: 예시 재활용 캐비닛 솔리드 우드, 서랍 4개 | D16: EXAMPLE-576 | E16: EXAMPLE-576-red | BP16: 목재 | BU16: 칠한 | BV16: 체리 | BW16: 빈티지 | BX16: 플러그 전원 | BY16: 110V/220V | BZ16: 유럽 ​​표준 플러그 | CD16: 예 | CE16: 견목 | CG16: 실크 | CH16: 기타 | CL16: 예 | CM16: <3.2 입방피트 | CN16: ≥27인치 | CO16: ≥30파운드 | CP16: 비충전식 배터리 | CS16: AAA 배터리 | CU16: 마 | CV16: 빨간색 | CW16: 예 | CX16: ≥5 | HK16: 색상 | HP16: 빨간색 | IV16: http://www.companyname.com/images/1250.main.jpg | JF16: 5 | JG16: 2.99 | JJ16: 9.2 | JK16: 2 | JL16: 3 | JM16: 4 | JP16: 1일 | JQ16: kr1 | JR16: 해당 상품을 직접 발송하겠습니다 | JT16: Republic of Korea
E17: 0 | JV17: 0
A18: 예시 3: 이는 4가지 변형이 있는 2가지 변형 테마(예: 사이즈 및 색상)가 있는 제품의 예입니다. 이는 "부모" 상품의 4가지 "자식" SKU입니다. 참고: 제품 이름, 제품 설명, 제품 세부 정보, 오퍼, 자격과 같은 제품 수준 정보의 경우 각 줄이 올바르게 작성되었는지, 정보가 일관되게 입력되었는지 확인하십시오. | B18: 29069 | C18: 예시 여성 티셔츠, 156 블랙 티셔츠 | D18: EXAMPLE-156-US | E18: EXAMPLE-156-US-Black-S | K18: 클래식 핏 티셔츠로 개성을 표현하세요. 100% 코튼으로 제작되어 탁월한 편안함과 내구성을 제공합니다. 티셔츠는 모던한 세련미를 구현한 독특하고 눈길을 끄는 그래픽이 특징입니다. 캐주얼한 외출이나 재킷 아래에 겹쳐 입기에 적합한 이 티셔츠는 모든 경우에 다재다능합니다. 형태를 유지하는 통기성 원단으로, 항상 필요한 옷장 필수품입니다. 자신을 표현하도록 디자인된 셔츠로 개성을 표현하고 편안함을 유지하세요. (문자 수: 493) | L18: 궁극의 편안함을 위한 100% 프리미엄 코튼. | M18: 시대를 초월한 디자인과 모던한 스타일이 만났습니다. | N18: 내구성 있는 원단으로 매일 입기에 완벽합니다. | O18: 세탁기로 세탁 가능하고 관리하기 쉽습니다. | P18: 모든 체형에 다재다능하게 맞습니다. | R18: http://www.companyname.com/images/1250.main.jpg | BW18: Y2K | CG18: 반짝임 | CY18: 35 | CZ18: 55 | DA18: 10 | EG18: 짧은 길이 | EH18: 예 | EI18: 민소매 | EJ18: 래글런 슬리브 | EK18: 아니요 | EL18: 가짜 버튼 | EM18: 버섯 | EN18: 예 | EO18: 신축성 없음 | EP18: 하프 플래킷 | EQ18: A | ER18: 봄/가을 | ES18: 손세탁 또는 전문 드라이클리닝 | ET18: 마른 | EU18: 신축성 없음 | EV18: 프린팅 없음 | EW18: 구매자가 제공 | EX18: 우븐 | EY18: 오프 숄더 | EZ18: 라틴 아메리카 | FA18: 스웨이드/PU | FB18: 스웨이드/PU | FC18: 안감 없음 | FD18: 200 | FE18: g/㎡ | FF18: 300 | FG18: g/㎡ | FH18: 250 | FI18: g/㎡ | HK18: 사이즈 × 색상 | HL18: 10000 - 미국/유럽 사이즈 | HM18: 10 - 알파 | HN18: S | HO18: 하얀색 | IC18: cm-g-ml | ID18: 0 | IF18: 36 | IG18: 28 | IN18: 33.9 | IO18: 35.5 | IP18: 26 | IQ18: 27.6 | IR18: 35.9 | IS18: 37.4 | IV18: http://www.companyname.com/images/1250.main.jpg | JF18: 5 | JG18: 2.99 | JJ18: 9.2 | JK18: 2 | JL18: 3 | JM18: 4 | JP18: 1일 | JQ18: kr1 | JR18: 해당 상품을 직접 발송하겠습니다 | JT18: Republic of Korea
B19: 29069 | C19: 예시 여성 티셔츠, 156 블랙 티셔츠 | D19: EXAMPLE-156-US | E19: EXAMPLE-156-US-Black-M | K19: 클래식 핏 티셔츠로 개성을 표현하세요. 100% 코튼으로 제작되어 탁월한 편안함과 내구성을 제공합니다. 티셔츠는 모던한 세련미를 구현한 독특하고 눈길을 끄는 그래픽이 특징입니다. 캐주얼한 외출이나 재킷 아래에 겹쳐 입기에 적합한 이 티셔츠는 모든 경우에 다재다능합니다. 형태를 유지하는 통기성 원단으로, 항상 필요한 옷장 필수품입니다. 자신을 표현하도록 디자인된 셔츠로 개성을 표현하고 편안함을 유지하세요. (문자 수: 493) | L19: 궁극의 편안함을 위한 100% 프리미엄 코튼. | M19: 시대를 초월한 디자인과 모던한 스타일이 만났습니다. | N19: 내구성 있는 원단으로 매일 입기에 완벽합니다. | O19: 세탁기로 세탁 가능하고 관리하기 쉽습니다. | P19: 모든 체형에 다재다능하게 맞습니다. | R19: http://www.companyname.com/images/1250.main.jpg | BW19: Y2K | CG19: 반짝임 | CY19: 35 | CZ19: 55 | DA19: 10 | EG19: 짧은 길이 | EH19: 예 | EI19: 민소매 | EJ19: 래글런 슬리브 | EK19: 아니요 | EL19: 가짜 버튼 | EM19: 버섯 | EN19: 예 | EO19: 신축성 없음 | EP19: 하프 플래킷 | EQ19: A | ER19: 봄/가을 | ES19: 손세탁 또는 전문 드라이클리닝 | ET19: 마른 | EU19: 신축성 없음 | EV19: 프린팅 없음 | EW19: 구매자가 제공 | EX19: 우븐 | EY19: 오프 숄더 | EZ19: 라틴 아메리카 | FA19: 스웨이드/PU | FB19: 스웨이드/PU | FC19: 안감 없음 | FD19: 200 | FE19: g/㎡ | FF19: 300 | FG19: g/㎡ | FH19: 250 | FI19: g/㎡ | HK19: 사이즈 × 색상 | HL19: 10000 - 미국/유럽 사이즈 | HM19: 10 - 알파 | HN19: M | HO19: 하얀색 | IC19: cm-g-ml | ID19: 2 | IF19: 40 | IG19: 29 | IN19: 35.5 | IO19: 37 | IP19: 27.6 | IQ19: 29.2 | IR19: 27.4 | IS19: 39 | IV19: http://www.companyname.com/images/1250.main.jpg | JF19: 5 | JG19: 2.99 | JJ19: 9.2 | JK19: 2 | JL19: 3 | JM19: 4 | JP19: 1일 | JQ19: kr1 | JR19: 해당 상품을 직접 발송하겠습니다 | JT19: Republic of Korea
B20: 29069 | C20: 예시 여성 티셔츠, 156 블랙 티셔츠 | D20: EXAMPLE-156-US | E20: EXAMPLE-156-US-red-S | K20: 클래식 핏 티셔츠로 개성을 표현하세요. 100% 코튼으로 제작되어 탁월한 편안함과 내구성을 제공합니다. 티셔츠는 모던한 세련미를 구현한 독특하고 눈길을 끄는 그래픽이 특징입니다. 캐주얼한 외출이나 재킷 아래에 겹쳐 입기에 적합한 이 티셔츠는 모든 경우에 다재다능합니다. 형태를 유지하는 통기성 원단으로, 항상 필요한 옷장 필수품입니다. 자신을 표현하도록 디자인된 셔츠로 개성을 표현하고 편안함을 유지하세요. (문자 수: 493) | L20: 궁극의 편안함을 위한 100% 프리미엄 코튼. | M20: 시대를 초월한 디자인과 모던한 스타일이 만났습니다. | N20: 내구성 있는 원단으로 매일 입기에 완벽합니다. | O20: 세탁기로 세탁 가능하고 관리하기 쉽습니다. | P20: 모든 체형에 다재다능하게 맞습니다. | R20: http://www.companyname.com/images/1250.main.jpg | BW20: Y2K | CG20: 반짝임 | CY20: 35 | CZ20: 55 | DA20: 10 | EG20: 짧은 길이 | EH20: 예 | EI20: 민소매 | EJ20: 래글런 슬리브 | EK20: 아니요 | EL20: 가짜 버튼 | EM20: 버섯 | EN20: 예 | EO20: 신축성 없음 | EP20: 하프 플래킷 | EQ20: A | ER20: 봄/가을 | ES20: 손세탁 또는 전문 드라이클리닝 | ET20: 마른 | EU20: 신축성 없음 | EV20: 프린팅 없음 | EW20: 구매자가 제공 | EX20: 우븐 | EY20: 오프 숄더 | EZ20: 라틴 아메리카 | FA20: 스웨이드/PU | FB20: 스웨이드/PU | FC20: 안감 없음 | FD20: 200 | FE20: g/㎡ | FF20: 300 | FG20: g/㎡ | FH20: 250 | FI20: g/㎡ | HK20: 사이즈 × 색상 | HL20: 10000 - 미국/유럽 사이즈 | HM20: 10 - 알파 | HN20: S | HO20: 아이보리 화이트 | IC20: cm-g-ml | ID20: 0 | IF20: 36 | IG20: 28 | IN20: 33.9 | IO20: 35.5 | IP20: 26 | IQ20: 27.6 | IR20: 35.9 | IS20: 37.4 | IV20: http://www.companyname.com/images/1250.main.jpg | JF20: 5 | JG20: 3.99 | JJ20: 9.2 | JK20: 2 | JL20: 3 | JM20: 4 | JP20: 1일 | JQ20: kr1 | JR20: 해당 상품을 직접 발송하겠습니다 | JT20: Republic of Korea
B21: 29069 | C21: 예시 여성 티셔츠, 156 블랙 티셔츠 | D21: EXAMPLE-156-US | E21: EXAMPLE-156-US-red-M | K21: 클래식 핏 티셔츠로 개성을 표현하세요. 100% 코튼으로 제작되어 탁월한 편안함과 내구성을 제공합니다. 티셔츠는 모던한 세련미를 구현한 독특하고 눈길을 끄는 그래픽이 특징입니다. 캐주얼한 외출이나 재킷 아래에 겹쳐 입기에 적합한 이 티셔츠는 모든 경우에 다재다능합니다. 형태를 유지하는 통기성 원단으로, 항상 필요한 옷장 필수품입니다. 자신을 표현하도록 디자인된 셔츠로 개성을 표현하고 편안함을 유지하세요. (문자 수: 493) | L21: 궁극의 편안함을 위한 100% 프리미엄 코튼. | M21: 시대를 초월한 디자인과 모던한 스타일이 만났습니다. | N21: 내구성 있는 원단으로 매일 입기에 완벽합니다. | O21: 세탁기로 세탁 가능하고 관리하기 쉽습니다. | P21: 모든 체형에 다재다능하게 맞습니다. | R21: http://www.companyname.com/images/1250.main.jpg | BW21: Y2K | CG21: 반짝임 | CY21: 35 | CZ21: 55 | DA21: 10 | EG21: 짧은 길이 | EH21: 예 | EI21: 민소매 | EJ21: 래글런 슬리브 | EK21: 아니요 | EL21: 가짜 버튼 | EM21: 버섯 | EN21: 예 | EO21: 신축성 없음 | EP21: 하프 플래킷 | EQ21: A | ER21: 봄/가을 | ES21: 손세탁 또는 전문 드라이클리닝 | ET21: 마른 | EU21: 신축성 없음 | EV21: 프린팅 없음 | EW21: 구매자가 제공 | EX21: 우븐 | EY21: 오프 숄더 | EZ21: 라틴 아메리카 | FA21: 스웨이드/PU | FB21: 스웨이드/PU | FC21: 안감 없음 | FD21: 200 | FE21: g/㎡ | FF21: 300 | FG21: g/㎡ | FH21: 250 | FI21: g/㎡ | HK21: 사이즈 × 색상 | HL21: 10000 - 미국/유럽 사이즈 | HM21: 10 - 알파 | HN21: M | HO21: 아이보리 화이트 | IC21: cm-g-ml | ID21: 2 | IF21: 40 | IG21: 29 | IN21: 35.5 | IO21: 37 | IP21: 27.6 | IQ21: 29.2 | IR21: 27.4 | IS21: 39 | IV21: http://www.companyname.com/images/1250.main.jpg | JF21: 5 | JG21: 3.99 | JJ21: 9.2 | JK21: 2 | JL21: 3 | JM21: 4 | JP21: 1일 | JQ21: kr1 | JR21: 해당 상품을 직접 발송하겠습니다 | JT21: Republic of Korea
B22: 12408 | C22: 예시 재활용 캐비닛 솔리드 우드, 서랍 4개 | D22: EXAMPLE-576 | E22: Example_Brand Night Stand with 4 Drawers (White, 21 inch) | BP22: 목재 | BU22: 칠한 | BV22: 체리 | BW22: 빈티지 | BX22: 플러그 전원 | BY22: 110V/220V | BZ22: 유럽 ​​표준 플러그 | CD22: 예 | CE22: 견목 | CG22: 실크 | CH22: 기타 | CL22: 예 | CM22: <3.2 입방피트 | CN22: ≥27인치 | CO22: ≥30파운드 | CP22: 비충전식 배터리 | CS22: AAA 배터리 | CU22: 마 | CV22: 빨간색 | CW22: 예 | CX22: ≥5 | HK22: 색상 × 크기 | HP22: 화이트 | HQ22: 21인치 | IV22: http://www.companyname.com/images/1250.main.jpg | JF22: 5 | JG22: 2.99 | JJ22: 9.2 | JK22: 2 | JL22: 3 | JM22: 4 | JP22: 1일 | JQ22: kr1 | JR22: 해당 상품을 직접 발송하겠습니다 | JT22: Republic of Korea
B23: 12408 | C23: 예시 재활용 캐비닛 솔리드 우드, 서랍 4개 | D23: EXAMPLE-576 | E23: Example_Brand Night Stand with 2 Drawers (White, 24 inch) | BP23: 목재 | BU23: 칠한 | BV23: 체리 | BW23: 빈티지 | BX23: 플러그 전원 | BY23: 110V/220V | BZ23: 유럽 ​​표준 플러그 | CD23: 예 | CE23: 견목 | CG23: 실크 | CH23: 기타 | CL23: 예 | CM23: <3.2 입방피트 | CN23: ≥27인치 | CO23: ≥30파운드 | CP23: 비충전식 배터리 | CS23: AAA 배터리 | CU23: 마 | CV23: 빨간색 | CW23: 예 | CX23: ≥5 | HK23: 색상 × 크기 | HP23: 화이트 | HQ23: 24인치 | IV23: http://www.companyname.com/images/1250.main.jpg | JF23: 5 | JG23: 2.99 | JJ23: 9.2 | JK23: 2 | JL23: 3 | JM23: 4 | JP23: 1일 | JQ23: kr1 | JR23: 해당 상품을 직접 발송하겠습니다 | JT23: Republic of Korea
B24: 12408 | C24: 예시 재활용 캐비닛 솔리드 우드, 서랍 4개 | D24: EXAMPLE-576 | E24: Example_Brand Night Stand with 2 Drawers (Grey, 21 inch) | BP24: 목재 | BU24: 칠한 | BV24: 체리 | BW24: 빈티지 | BX24: 플러그 전원 | BY24: 110V/220V | BZ24: 유럽 ​​표준 플러그 | CD24: 예 | CE24: 견목 | CG24: 실크 | CH24: 기타 | CL24: 예 | CM24: <3.2 입방피트 | CN24: ≥27인치 | CO24: ≥30파운드 | CP24: 비충전식 배터리 | CS24: AAA 배터리 | CU24: 마 | CV24: 빨간색 | CW24: 예 | CX24: ≥5 | HK24: 색상 × 크기 | HP24: 그레이 | HQ24: 21인치 | IV24: http://www.companyname.com/images/1250.main.jpg | JF24: 5 | JG24: 2.99 | JJ24: 9.2 | JK24: 2 | JL24: 3 | JM24: 4 | JP24: 1일 | JQ24: kr1 | JR24: 해당 상품을 직접 발송하겠습니다 | JT24: Republic of Korea
B25: 12408 | C25: 예시 재활용 캐비닛 솔리드 우드, 서랍 4개 | D25: EXAMPLE-576 | E25: Example_Brand Night Stand with 2 Drawers (Grey, 24 inch) | BP25: 목재 | BU25: 칠한 | BV25: 체리 | BW25: 빈티지 | BX25: 플러그 전원 | BY25: 110V/220V | BZ25: 유럽 ​​표준 플러그 | CD25: 예 | CE25: 견목 | CG25: 실크 | CH25: 기타 | CL25: 예 | CM25: <3.2 입방피트 | CN25: ≥27인치 | CO25: ≥30파운드 | CP25: 비충전식 배터리 | CS25: AAA 배터리 | CU25: 마 | CV25: 빨간색 | CW25: 예 | CX25: ≥5 | HK25: 색상 × 크기 | HP25: 그레이 | HQ25: 24인치 | IV25: http://www.companyname.com/images/1250.main.jpg | JF25: 5 | JG25: 2.99 | JJ25: 9.2 | JK25: 2 | JL25: 3 | JM25: 4 | JP25: 1일 | JQ25: kr1 | JR25: 해당 상품을 직접 발송하겠습니다 | JT25: Republic of Korea

Sheet 데이터 정의
A1: 템플릿을 완성하는 방법
A2: Group Name | B2: Field Name | C2: Local Label Name | D2: Definition and Use | E2: Accepted Values | F2: Example | G2: Required?
A3: 제품 아이덴티티 - 이는 구매자에게 중요한 속성이며 모든 항목에 채워야 합니다. 일부는 오퍼를 만드는 데 필요합니다.
B4: t_0_category | C4: Category | D4: 단일 상품 카테고리 업로드만 지원합니다. 카테고리 ID는 드롭다운에 사전 설정되어 있습니다. | E4: 적절한 카테고리를 입력하세요. | F4: 13788 | G4: 필수의
B5: t_0_productname | C5: Product Name | D5: MMS 가이드라인을 따릅니다. 최대 500자까지 허용되며, 빈 줄이나 두 개 이상의 연속된 공백이 포함되어서는 안 됩니다. | E5: 브랜드, 색상, 핏, 사이즈를 포함한 품목 이름을 500자 이내로 입력하세요. | F5: Robert Graham Men's Maya Bay Short Sleeve Classic Fit Shirt, Cranberry, X-Large | G5: 필수의
B6: t_0_contributiongoods | C6: Contribution Goods | D6: 플랫폼에서 제공자에게 부모 제품 링크를 표시하고 관리하기 위해 제공하는 코드로, 판매자가 채웁니다. 매장 내에서 고유해야 합니다. 동일한 기여 상품 값을 가진 행은 시스템에서 동일한 부모 제품 아래의 다른 자식 SKU로 처리됩니다. SKU에서 앞뒤 공백을 사용하지 마십시오. | E6: 이 속성은 기여자가 지정한 SKU 번호를 나타냅니다. | F6: ABC123 | G6: 필수의
B7: t_0_contributionsku | C7: Contribution SKU | D7: 플랫폼에서 공급업체에 제공하는 하위 제품 링크의 표시 및 관리를 위한 코드로, 판매자가 채웁니다. 매장 내에서 고유해야 합니다. SKU에 앞이나 뒤에 공백을 사용하지 마십시오. | E7: 이 속성은 기여자가 지정한 SKU 번호를 나타냅니다. | F7: ABC123 | G7: 필수의
B8: t_0_brand | C8: Brand | D8: 제품에 브랜드 정보가 필요한 경우, 해당 제품의 브랜드와 상표를 모두 선택하세요. | E8: 제품의 브랜드명을 선택하세요 | F8: Nike | G8: 선택 과목
B9: t_0_trademark | C9: Trademark | D9: 제품에 브랜드 정보가 필요한 경우 해당 브랜드와 상표를 모두 선택하십시오. 연관시키고 싶은 브랜드와 상표를 선택할 때는 주의하십시오. | E9: 제품의 상표명을 선택하세요 | F9: Nike | G9: 선택 과목
A10: 제품 설명 - 이러한 속성은 고객이 찾아보기나 검색을 통해 사이트에서 제품을 찾는 방법에 영향을 미칩니다.
B11: t_1_productdescription | C11: Product Description | D11: 제품에 대한 텍스트 설명. | E11: MMS 가이드라인을 따릅니다. 최대 2000자까지 가능하며, 서식 있는 텍스트 형식은 지원하지 않습니다. | F11: Long sleeve v-neck cardigan with a ribbed waistline and pockets with bow detailing | G11: 선택 과목
B12: t_1_bulletpoint | C12: Bullet Point | D12: 제품의 특정 측면에 대한 요점을 통해 호출되는 간략한 설명 텍스트입니다. 이는 제품 사진 바로 아래 또는 옆에 표시되므로 이러한 필드에 흥미로운 정보를 입력하는 것이 유용합니다. 요점은 자동으로 삽입됩니다. | E12: MMS 가이드라인을 따릅니다. 최대 700자, 서식 있는 텍스트 포맷은 지원하지 않습니다. 셀당 하나의 글머리 기호를 업로드할 수 있습니다. | F12: Made with nourishing pure aloe vera gel | G12: 선택 과목
B13: t_1_detailimagesurl | C13: Detail Images URL | D13: 제품의 세부 이미지에 대한 URL입니다. 이러한 이미지는 고객이 클릭하여 제품과 관련된 다른 뷰를 볼 때 세부 정보 페이지에 표시됩니다. 예를 들어, 이 필드를 사용하여 제품의 라벨 정보나 포장을 표시할 수 있습니다. 다른 뷰가 있는 추가 이미지를 항목에 업로드하거나 감정적인 주변 환경을 추가 이미지로 업로드합니다. | E13: 이미지 호스팅 웹사이트에서 URL을 얻어 해당 셀에 입력합니다. i. 종횡비: 최소 1:3; ii. 너비 또는 높이: 최소 480px; iii. 파일 크기: 최대 3MB; iv. 파일 유형: jpeg, jpg, png | F13: http://www.companyname.com/images/1250.main.jpg | G13: 선택 과목
B14: t_1_detailvideourl | C14: Detail Video URL | D14: 귀하의 제품에 대한 세부 비디오의 URL입니다. 세부 비디오는 제품 세부 정보 섹션의 맨 위에 표시됩니다. | E14: 이미지 호스팅 웹사이트에서 URL을 얻어 해당 셀에 입력합니다. i. 종횡비: 1:1, 4:3, 16:9 ii. 해상도: 최소 720p iii. 지속 시간: 최대 180초 iv. 파일 크기: 최대 300MB v. 파일 유형: wmv, avi, 3gp, mov, mp4, flv, rmvb, mkv, m4v, x-flv | F14: http://www.companyname.com/videos/1250..mp4 | G14: 선택 과목
A15: 판매 속성(최소 1개, 최대 2개) - 제품에 사용되는 이러한 속성은 다양한 변형으로 제공됩니다.
B16: t_3_variationtheme | C16: Variation Theme | D16: 부모 제품이 달라질 수 있는 매개변수를 설명합니다. 이 필드에 대한 값 입력은 동일한 제품의 모든 SKU에 대해 동일해야 합니다. 예: 제품이 크기에 따라 달라지는 경우 값 크기를 입력합니다. 제품이 색상에 따라 달라지는 경우 값 색상을 입력합니다. 변형 테마에 사용되는 용어는 판매자인 귀하가 만듭니다. (예: '수량'은 선택한 숫자일 수 있음). | E16: 선택하고 적용 가능한 변형 테마를 선택하세요. | F16: Color × Size | G16: 필수의
A17: 변형 - 이는 구매자에게 중요한 속성이며 제품 SKU에 채워져야 합니다.
B18: t_5_skuimagesurl | C18: SKU Images URL | D18: 고객이 제품과 관련된 다른 뷰를 보기 위해 클릭하면 SKU 이미지가 제품 페이지 상단에 표시됩니다. 다른 SKU 이미지는 제품의 회전목마를 형성합니다. 예를 들어, 이 필드를 사용하여 제품의 라벨 정보나 포장을 표시할 수 있습니다. 다른 뷰가 있는 추가 이미지를 항목에 업로드하거나 감정이 담긴 주변 이미지를 추가 이미지로 업로드합니다. | E18: a. For clothes: i. Aspect ratio: 3:4 ii. Width: min of 1340px iii. Height: min of 1785px iv. File size: max of 3MB v. File types: jpeg, jpg, png b. For other products: i. Aspect ratio: 1:1 ii. Width or height: min of 800px iii. File size: max of 3MB iv. File types: jpeg, jpg, png | F18: http://www.companyname.com/images/1250.main.jpg | G18: 필수의
B19: t_5_quantity | C19: Quantity | D19: 판매할 품목의 수량을 입력하세요. 이는 현재 INVENTORY 약정입니다. 모든 "자식" 또는 독립형 품목에 수량이 필요합니다. 제품 정보를 처음 제출할 때 비워두면 품목이 "재고 없음"으로 표시됩니다. | E19: 판매할 품목의 수량을 입력하세요. 이는 현재 재고 약정(정수)입니다. | F19: 152 | G19: 필수의
B20: t_5_baseprice_krw | C20: Base Price - krw | D20: 기준 가격은 비용과 예상 이익을 반영해야 합니다. 판매된 각 제품의 운영 가격을 기준으로 판매 수익을 받게 됩니다. 최종 소매 가격은 지불 정산과 직접 연결되지 않습니다. 기준 가격은 목록 가격보다 낮아야 합니다. | E20: The price range is ₩ 1-₩ 9,999,999,999, with a maximum of 0 decimal places, and will be rounded up. | F20: 3000 | G20: 필수의
B21: t_5_listprice_krw | C21: List Price - krw | D21: 가격표 제조업체가 정한 제품의 제안 또는 권장 소매 가격입니다. | E21: The price range is ₩ 1-₩ 9,999,999,999, with a maximum of 0 decimal places, and will be rounded up. | F21: 3500 | G21: 선택 과목
B22: t_5_weight_g | C22: Weight - g | E22: The weight range is 0.1 g-9,999,999.9 g, with a maximum of 1 decimal place, and will be rounded up | F22: 10.2 | G22: 필수의
B23: t_5_length_cm | C23: Length - cm | E23: The length range is 0.1 cm-9,999.9 cm, with a maximum of 1 decimal point, and will be rounded up | F23: 3.1 | G23: 필수의
B24: t_5_width_cm | C24: Width - cm | E24: The length range is 0.1 cm-9,999.9 cm, with a maximum of 1 decimal point, and will be rounded up | F24: 2.1 | G24: 필수의
B25: t_5_height_cm | C25: Height - cm | E25: The length range is 0.1 cm-9,999.9 cm, with a maximum of 1 decimal point, and will be rounded up | F25: 1.1 | G25: 필수의
B26: t_5_externalproductidtype | C26: External Product ID Type | D26: 제품 ID 필드에 입력된 표준 고유 식별자의 유형입니다. 제품 ID가 제공된 경우 필수 필드입니다. | E26: 제품 ID 필드에 입력된 표준 고유 식별자의 유형입니다. 제품 ID가 제공된 경우 필수 필드입니다. | F26: UPC | G26: 선택 과목
B27: t_5_externalproductid | C27: External Product ID | D27: 제품을 고유하게 식별하는 표준 영숫자 문자열입니다. 이는 GCID(16자 영숫자), UPC 또는 EAN일 수 있습니다. product_id_type이 제공된 경우 필수 필드입니다. | E27: 선택된 유형에 따라 해당 외부 제품 ID 값을 제공합니다. | F27: 714532191586 | G27: 선택 과목
A28: 제공 - 이러한 속성은 사이트의 고객이 귀하의 제품을 구매할 수 있도록 하는 데 필요합니다.
B29: t_6_handlingtime | C29: Handling Time | D29: 품목에 대한 주문을 받은 시점과 품목을 배송할 수 있는 시점 사이의 시간(일)을 나타냅니다. 기본 생산 시간은 1~2영업일입니다. 생산 시간이 2영업일보다 큰 경우 이 필드를 사용합니다. | E29: MMS와 동일. 1, 2일만 지원. | F29: 1 day | G29: 필수의
B30: t_6_shippingtemplate | C30: Shipping Template | D30: 판매자는 비즈니스 요구 사항과 사용 사례에 따라 선박 구성 세트를 만들 수 있습니다. 선박 구성은 지역 기반일 수 있으며 해당 지역의 SLA 및 요금을 설정하는 규칙이 있습니다. 오퍼를 만들기 위해 제품을 나열할 때 판매자는 제품에 대한 선박 구성을 하나 선택해야 합니다. 선박 구성은 웹사이트에서 유효한 선박 옵션을 검색하는 데 사용됩니다. | E30: 먼저 MMS에서 배송 템플릿을 만드는 것을 완료해야 하며, 매장에서 사용 가능한 모든 배송 템플릿 이름이 여기에 표시됩니다. | F30: "Free Shipping Template", "Default Template" | G30: 필수의
B31: t_6_fulfillmentchannel | C31: Fulfillment Channel | G31: 필수의
B32: t_6_itemtaxcode | C32: Item Tax Code | D32: 품목 세금 코드(ITC)는 해당 제품 범주에 대해 규정된 올바른 VAT 비율과 제품을 매치합니다. 제품에 ITC가 할당되지 않은 경우 "계산 설정"의 기본값이 적용됩니다. | E32: temu.com에서 제공한 품목 세금 코드를 입력하세요. | F32: GEN STANDARD | G32: 선택 과목
A33: 자격 - 품목이 판매되는 국가 또는 지역의 소비자법을 준수하는 데 사용되는 속성
B34: sunny_9_product_guide | C34: Product Guide | E34: 이미지 호스팅 웹사이트에서 매뉴얼의 URL을 얻어서 셀에 채워주세요. 제품 가이드 제출 요건: a. 파일 크기: 최대 15MB b. 파일 유형: pdf | F34: http://www.companyname.com/guide/1250.pdf | G34: 선택 과목

Sheet Template
A1: 처리 결과 | E1: 제품 식별 정보 | T1: 제품 설명 | DS1: 제품 세부 정보 | IF1: 판매 특성 | IT1: 옵션 | JX1: 공급 | KB1: 자격요건
A2: 제품 ID | B2: SKU ID | C2: 상태 | D2: 세부 정보 | E2: 카테고리 | F2: 카테고리 이름 | G2: 제품 유형 | H2: 맞춤 제작 가공 기법 | I2: 주요 기법 | J2: 보조 기법 | K2: 보조 기법 | L2: 제품명 | M2: outGoodsSn | N2: outSkuSn | O2: 업데이트 또는 추가 | P2: 제품 ID | Q2: SKU ID | R2: 브랜드 | S2: 상표 | T2: 제품 설명 | U2: 글머리 기호 | V2: 글머리 기호 | W2: 글머리 기호 | X2: 글머리 기호 | Y2: 글머리 기호 | Z2: 글머리 기호 | AA2: 상세 이미지 URL | AB2: 상세 이미지 URL | AC2: 상세 이미지 URL | AD2: 상세 이미지 URL | AE2: 상세 이미지 URL | AF2: 상세 이미지 URL | AG2: 상세 이미지 URL | AH2: 상세 이미지 URL | AI2: 상세 이미지 URL | AJ2: 상세 이미지 URL | AK2: 상세 이미지 URL | AL2: 상세 이미지 URL | AM2: 상세 이미지 URL | AN2: 상세 이미지 URL | AO2: 상세 이미지 URL | AP2: 상세 이미지 URL | AQ2: 상세 이미지 URL | AR2: 상세 이미지 URL | AS2: 상세 이미지 URL | AT2: 상세 이미지 URL | AU2: 상세 이미지 URL | AV2: 상세 이미지 URL | AW2: 상세 이미지 URL | AX2: 상세 이미지 URL | AY2: 상세 이미지 URL | AZ2: 상세 이미지 URL | BA2: 상세 이미지 URL | BB2: 상세 이미지 URL | BC2: 상세 이미지 URL | BD2: 상세 이미지 URL | BE2: 상세 이미지 URL | BF2: 상세 이미지 URL | BG2: 상세 이미지 URL | BH2: 상세 이미지 URL | BI2: 상세 이미지 URL | BJ2: 상세 이미지 URL | BK2: 상세 이미지 URL | BL2: 상세 이미지 URL | BM2: 상세 이미지 URL | BN2: 상세 이미지 URL | BO2: 상세 이미지 URL | BP2: 상세 이미지 URL | BQ2: 상세 이미지 URL | BR2: 상세 이미지 URL | BS2: 상세 이미지 URL | BT2: 상세 이미지 URL | BU2: 상세 이미지 URL | BV2: 상세 이미지 URL | BW2: 상세 이미지 URL | BX2: 상세 이미지 URL | BY2: 상세 이미지 URL | BZ2: 상세 이미지 URL | CA2: 상세 이미지 URL | CB2: 상세 이미지 URL | CC2: 상세 이미지 URL | CD2: 상세 이미지 URL | CE2: 상세 이미지 URL | CF2: 상세 이미지 URL | CG2: 상세 이미지 URL | CH2: 상세 이미지 URL | CI2: 상세 이미지 URL | CJ2: 상세 이미지 URL | CK2: 상세 이미지 URL | CL2: 상세 이미지 URL | CM2: 상세 이미지 URL | CN2: 상세 이미지 URL | CO2: 상세 이미지 URL | CP2: 상세 이미지 URL | CQ2: 상세 이미지 URL | CR2: 상세 이미지 URL | CS2: 상세 이미지 URL | CT2: 상세 이미지 URL | CU2: 상세 이미지 URL | CV2: 상세 이미지 URL | CW2: 상세 이미지 URL | CX2: 상세 이미지 URL | CY2: 상세 이미지 URL | CZ2: 상세 이미지 URL | DA2: 상세 이미지 URL | DB2: 상세 이미지 URL | DC2: 상세 이미지 URL | DD2: 상세 이미지 URL | DE2: 상세 이미지 URL | DF2: 상세 이미지 URL | DG2: 상세 이미지 URL | DH2: 상세 이미지 URL | DI2: 상세 이미지 URL | DJ2: 상세 이미지 URL | DK2: 상세 이미지 URL | DL2: 상세 이미지 URL | DM2: 상세 이미지 URL | DN2: 상세 이미지 URL | DO2: 상세 이미지 URL | DP2: 상세 이미지 URL | DQ2: 상세 이미지 URL | DR2: 상세 동영상 URL | DS2: 195 - 다이어트 유형 | DT2: 195 - 다이어트 유형 | DU2: 4118 - 전문 | DV2: 4118 - 전문 | DW2: 4121 - 알레르기 정보 | DX2: 4121 - 알레르기 정보 | DY2: 4121 - 알레르기 정보 | DZ2: 4121 - 알레르기 정보 | EA2: 4121 - 알레르기 정보 | EB2: 4121 - 알레르기 정보 | EC2: 4121 - 알레르기 정보 | ED2: 4121 - 알레르기 정보 | EE2: 4121 - 알레르기 정보 | EF2: 4121 - 알레르기 정보 | EG2: 4121 - 알레르기 정보 | EH2: 4121 - 알레르기 정보 | EI2: 4121 - 알레르기 정보 | EJ2: 4121 - 알레르기 정보 | EK2: 4121 - 알레르기 정보 | EL2: 4121 - 알레르기 정보 | EM2: 4121 - 알레르기 정보 | EN2: 4121 - 알레르기 정보 | EO2: 4121 - 알레르기 정보 | EP2: 4121 - 알레르기 정보 | EQ2: 4121 - 알레르기 정보 | ER2: 4121 - 알레르기 정보 | ES2: 4121 - 알레르기 정보 | ET2: 4121 - 알레르기 정보 | EU2: 4121 - 알레르기 정보 | EV2: 4121 - 알레르기 정보 | EW2: 4121 - 알레르기 정보 | EX2: 4121 - 알레르기 정보 | EY2: 4121 - 알레르기 정보 | EZ2: 4121 - 알레르기 정보 | FA2: 4121 - 알레르기 정보 | FB2: 4121 - 알레르기 정보 | FC2: 4121 - 알레르기 정보 | FD2: 4121 - 알레르기 정보 | FE2: 4121 - 알레르기 정보 | FF2: 4121 - 알레르기 정보 | FG2: 4121 - 알레르기 정보 | FH2: 4121 - 알레르기 정보 | FI2: 4121 - 알레르기 정보 | FJ2: 4121 - 알레르기 정보 | FK2: 4121 - 알레르기 정보 | FL2: 4121 - 알레르기 정보 | FM2: 4121 - 알레르기 정보 | FN2: 4121 - 알레르기 정보 | FO2: 4121 - 알레르기 정보 | FP2: 4121 - 알레르기 정보 | FQ2: 4121 - 알레르기 정보 | FR2: 4121 - 알레르기 정보 | FS2: 4121 - 알레르기 정보 | FT2: 4121 - 알레르기 정보 | FU2: 4121 - 알레르기 정보 | FV2: 4121 - 알레르기 정보 | FW2: 4121 - 알레르기 정보 | FX2: 4121 - 알레르기 정보 | FY2: 4121 - 알레르기 정보 | FZ2: 4121 - 알레르기 정보 | GA2: 4121 - 알레르기 정보 | GB2: 4121 - 알레르기 정보 | GC2: 4121 - 알레르기 정보 | GD2: 4121 - 알레르기 정보 | GE2: 4121 - 알레르기 정보 | GF2: 4121 - 알레르기 정보 | GG2: 4121 - 알레르기 정보 | GH2: 4121 - 알레르기 정보 | GI2: 4121 - 알레르기 정보 | GJ2: 4121 - 알레르기 정보 | GK2: 4121 - 알레르기 정보 | GL2: 4121 - 알레르기 정보 | GM2: 4121 - 알레르기 정보 | GN2: 4121 - 알레르기 정보 | GO2: 4121 - 알레르기 정보 | GP2: 4121 - 알레르기 정보 | GQ2: 4121 - 알레르기 정보 | GR2: 4121 - 알레르기 정보 | GS2: 4121 - 알레르기 정보 | GT2: 4121 - 알레르기 정보 | GU2: 4121 - 알레르기 정보 | GV2: 4121 - 알레르기 정보 | GW2: 4121 - 알레르기 정보 | GX2: 4121 - 알레르기 정보 | GY2: 4121 - 알레르기 정보 | GZ2: 4121 - 알레르기 정보 | HA2: 4121 - 알레르기 정보 | HB2: 4121 - 알레르기 정보 | HC2: 4121 - 알레르기 정보 | HD2: 4121 - 알레르기 정보 | HE2: 4121 - 알레르기 정보 | HF2: 4121 - 알레르기 정보 | HG2: 4121 - 알레르기 정보 | HH2: 4121 - 알레르기 정보 | HI2: 4121 - 알레르기 정보 | HJ2: 4121 - 알레르기 정보 | HK2: 4121 - 알레르기 정보 | HL2: 4121 - 알레르기 정보 | HM2: 4121 - 알레르기 정보 | HN2: 4121 - 알레르기 정보 | HO2: 4121 - 알레르기 정보 | HP2: 4121 - 알레르기 정보 | HQ2: 4121 - 알레르기 정보 | HR2: 4121 - 알레르기 정보 | HS2: 6210 - USDA 인증 | HT2: 6440 - 유통 기한 | HU2: 4110 - 생산일자 | HV2: 4115 - 유효 기간 - value | HW2: 4115 - 유효 기간 - unit | HX2: 7413 - 식품 원재료 목록 | HY2: 7414 - 재료 | HZ2: 7739 - 보관 조건 및 형태 | IA2: 7739 - 보관 조건 및 형태 | IB2: 7739 - 보관 조건 및 형태 | IC2: 7738 - 처리 방법 | ID2: 7738 - 처리 방법 | IE2: 7738 - 처리 방법 | IF2: 옵션 테마 | IG2: 색상 | IH2: 사이즈 | II2: 스타일 | IJ2: 재료 | IK2: 풍미 | IL2: 해당하는 사람들 | IM2: 용량 | IN2: 구성 | IO2: 무게 | IP2: 항목 | IQ2: 수량 | IR2: 모델 | IS2: 머리 길이 | IT2: SKU 이미지 URL | IU2: SKU 이미지 URL | IV2: SKU 이미지 URL | IW2: SKU 이미지 URL | IX2: SKU 이미지 URL | IY2: SKU 이미지 URL | IZ2: SKU 이미지 URL | JA2: SKU 이미지 URL | JB2: SKU 이미지 URL | JC2: SKU 이미지 URL | JD2: 식재료 | JE2: 수량 | JF2: 기본 가격 - KRW | JG2: 참고 링크: | JH2: 정가 - KRW | JI2: 택배 무게 - g | JJ2: 길이 - cm | JK2: 너비 - cm | JL2: 높이 - cm | JM2: SKU 유형 | JN2: 개별 포장 | JO2: 총 포장 수량 | JP2: 포장 단위 | JQ2: 총 상품 수량 | JR2: 상품 단위 | JS2: 순함량 | JT2: 총 순함량 | JU2: 순함량 단위 | JV2: 외부 제품 ID 유형 | JW2: 외부 제품 ID | JX2: 배송 템플릿 | JY2: 처리 시간 | JZ2: 주문 처리 채널 | KA2: 상품 세금 코드(ITC) | KB2: 원산지 | KC2: 원산지 시/도 | KD2: SKU 포장 정보(눈에 보이는 라벨 포함) | KE2: SKU 포장 정보(눈에 보이는 라벨 포함) | KF2: SKU 포장 정보(눈에 보이는 라벨 포함) | KG2: SKU 포장 정보(눈에 보이는 라벨 포함) | KH2: SKU 포장 정보(눈에 보이는 라벨 포함) | KI2: SKU 포장 정보(눈에 보이는 라벨 포함) | KJ2: SKU 포장 정보(눈에 보이는 라벨 포함) | KK2: SKU 포장 정보(눈에 보이는 라벨 포함) | KL2: SKU 포장 정보(눈에 보이는 라벨 포함) | KM2: SKU 포장 정보(눈에 보이는 라벨 포함) | KN2: SKU 포장 정보(눈에 보이는 라벨 포함) | KO2: SKU 포장 정보(눈에 보이는 라벨 포함) | KP2: SKU 포장 정보(눈에 보이는 라벨 포함) | KQ2: SKU 포장 정보(눈에 보이는 라벨 포함) | KR2: SKU 포장 정보(눈에 보이는 라벨 포함) | KS2: SKU 포장 정보(눈에 보이는 라벨 포함) | KT2: SKU 포장 정보(눈에 보이는 라벨 포함) | KU2: SKU 포장 정보(눈에 보이는 라벨 포함) | KV2: SKU 포장 정보(눈에 보이는 라벨 포함) | KW2: SKU 포장 정보(눈에 보이는 라벨 포함) | KX2: SKU 포장 정보(눈에 보이는 라벨 포함) | KY2: SKU 포장 정보(눈에 보이는 라벨 포함) | KZ2: SKU 포장 정보(눈에 보이는 라벨 포함) | LA2: SKU 포장 정보(눈에 보이는 라벨 포함) | LB2: SKU 포장 정보(눈에 보이는 라벨 포함) | LC2: SKU 포장 정보(눈에 보이는 라벨 포함) | LD2: SKU 포장 정보(눈에 보이는 라벨 포함) | LE2: SKU 포장 정보(눈에 보이는 라벨 포함) | LF2: SKU 포장 정보(눈에 보이는 라벨 포함) | LG2: SKU 포장 정보(눈에 보이는 라벨 포함) | LH2: SKU 포장 정보(눈에 보이는 라벨 포함) | LI2: SKU 포장 정보(눈에 보이는 라벨 포함) | LJ2: SKU 포장 정보(눈에 보이는 라벨 포함) | LK2: SKU 포장 정보(눈에 보이는 라벨 포함) | LL2: SKU 포장 정보(눈에 보이는 라벨 포함) | LM2: SKU 포장 정보(눈에 보이는 라벨 포함) | LN2: SKU 포장 정보(눈에 보이는 라벨 포함) | LO2: SKU 포장 정보(눈에 보이는 라벨 포함) | LP2: SKU 포장 정보(눈에 보이는 라벨 포함) | LQ2: SKU 포장 정보(눈에 보이는 라벨 포함) | LR2: SKU 포장 정보(눈에 보이는 라벨 포함) | LS2: SKU 포장 정보(눈에 보이는 라벨 포함) | LT2: SKU 포장 정보(눈에 보이는 라벨 포함) | LU2: SKU 포장 정보(눈에 보이는 라벨 포함) | LV2: SKU 포장 정보(눈에 보이는 라벨 포함) | LW2: 원산지 라벨 및 제조업체 정보 | LX2: 원산지 라벨 및 제조업체 정보 | LY2: 원산지 라벨 및 제조업체 정보 | LZ2: 원산지 라벨 및 제조업체 정보 | MA2: 원산지 라벨 및 제조업체 정보 | MB2: 제품 가이드 - English
A3: Reserved line, prohibit any operation. | B3: Reserved line, prohibit any operation. | C3: Reserved line, prohibit any operation. | D3: Reserved line, prohibit any operation. | E3: eyJ0ZW1wbGF0ZV9pZCI6MjgzMzY4NDA4ODM0ODc4LCJ0ZW1wbGF0ZV9sYW5ndWFnZSI6ImtvIiwic2l0ZV9pZCI6MTE5LCJ2ZXJzaW9uIjoiMy4wLjAiLCJ0eXBlIjowfQ== | F3: Reserved line, prohibit any operation. | G3: Reserved line, prohibit any operation. | H3: Reserved line, prohibit any operation. | I3: Reserved line, prohibit any operation. | J3: Reserved line, prohibit any operation. | K3: Reserved line, prohibit any operation. | L3: Reserved line, prohibit any operation. | M3: Reserved line, prohibit any operation. | N3: Reserved line, prohibit any operation. | O3: Reserved line, prohibit any operation. | P3: Reserved line, prohibit any operation. | Q3: Reserved line, prohibit any operation. | R3: Reserved line, prohibit any operation. | S3: Reserved line, prohibit any operation. | T3: Reserved line, prohibit any operation. | U3: Reserved line, prohibit any operation. | V3: Reserved line, prohibit any operation. | W3: Reserved line, prohibit any operation. | X3: Reserved line, prohibit any operation. | Y3: Reserved line, prohibit any operation. | Z3: Reserved line, prohibit any operation. | AA3: Reserved line, prohibit any operation. | AB3: Reserved line, prohibit any operation. | AC3: Reserved line, prohibit any operation. | AD3: Reserved line, prohibit any operation. | AE3: Reserved line, prohibit any operation. | AF3: Reserved line, prohibit any operation. | AG3: Reserved line, prohibit any operation. | AH3: Reserved line, prohibit any operation. | AI3: Reserved line, prohibit any operation. | AJ3: Reserved line, prohibit any operation. | AK3: Reserved line, prohibit any operation. | AL3: Reserved line, prohibit any operation. | AM3: Reserved line, prohibit any operation. | AN3: Reserved line, prohibit any operation. | AO3: Reserved line, prohibit any operation. | AP3: Reserved line, prohibit any operation. | AQ3: Reserved line, prohibit any operation. | AR3: Reserved line, prohibit any operation. | AS3: Reserved line, prohibit any operation. | AT3: Reserved line, prohibit any operation. | AU3: Reserved line, prohibit any operation. | AV3: Reserved line, prohibit any operation. | AW3: Reserved line, prohibit any operation. | AX3: Reserved line, prohibit any operation. | AY3: Reserved line, prohibit any operation. | AZ3: Reserved line, prohibit any operation. | BA3: Reserved line, prohibit any operation. | BB3: Reserved line, prohibit any operation. | BC3: Reserved line, prohibit any operation. | BD3: Reserved line, prohibit any operation. | BE3: Reserved line, prohibit any operation. | BF3: Reserved line, prohibit any operation. | BG3: Reserved line, prohibit any operation. | BH3: Reserved line, prohibit any operation. | BI3: Reserved line, prohibit any operation. | BJ3: Reserved line, prohibit any operation. | BK3: Reserved line, prohibit any operation. | BL3: Reserved line, prohibit any operation. | BM3: Reserved line, prohibit any operation. | BN3: Reserved line, prohibit any operation. | BO3: Reserved line, prohibit any operation. | BP3: Reserved line, prohibit any operation. | BQ3: Reserved line, prohibit any operation. | BR3: Reserved line, prohibit any operation. | BS3: Reserved line, prohibit any operation. | BT3: Reserved line, prohibit any operation. | BU3: Reserved line, prohibit any operation. | BV3: Reserved line, prohibit any operation. | BW3: Reserved line, prohibit any operation. | BX3: Reserved line, prohibit any operation. | BY3: Reserved line, prohibit any operation. | BZ3: Reserved line, prohibit any operation. | CA3: Reserved line, prohibit any operation. | CB3: Reserved line, prohibit any operation. | CC3: Reserved line, prohibit any operation. | CD3: Reserved line, prohibit any operation. | CE3: Reserved line, prohibit any operation. | CF3: Reserved line, prohibit any operation. | CG3: Reserved line, prohibit any operation. | CH3: Reserved line, prohibit any operation. | CI3: Reserved line, prohibit any operation. | CJ3: Reserved line, prohibit any operation. | CK3: Reserved line, prohibit any operation. | CL3: Reserved line, prohibit any operation. | CM3: Reserved line, prohibit any operation. | CN3: Reserved line, prohibit any operation. | CO3: Reserved line, prohibit any operation. | CP3: Reserved line, prohibit any operation. | CQ3: Reserved line, prohibit any operation. | CR3: Reserved line, prohibit any operation. | CS3: Reserved line, prohibit any operation. | CT3: Reserved line, prohibit any operation. | CU3: Reserved line, prohibit any operation. | CV3: Reserved line, prohibit any operation.
A4: t_0_Goods Id | B4: t_0_Sku Id | C4: t_0_Status | D4: t_0_Details | E4: t_1_Category | F4: t_1_Category Name | G4: t_1_Product type | H4: t_1_Customization processing technique | I4: t_1_Primary technique | J4: t_1_Secondary technique | K4: t_1_Secondary technique | L4: t_1_Product Name | M4: t_1_Contribution Goods | N4: t_1_Contribution SKU | O4: t_1_Update or Add | P4: t_1_Goods Id | Q4: t_1_Sku Id | R4: t_1_Brand | S4: t_1_Trademark | T4: t_2_Product Description | U4: t_2_Bullet Point | V4: t_2_Bullet Point | W4: t_2_Bullet Point | X4: t_2_Bullet Point | Y4: t_2_Bullet Point | Z4: t_2_Bullet Point | AA4: t_2_Detail Images URL | AB4: t_2_Detail Images URL | AC4: t_2_Detail Images URL | AD4: t_2_Detail Images URL | AE4: t_2_Detail Images URL | AF4: t_2_Detail Images URL | AG4: t_2_Detail Images URL | AH4: t_2_Detail Images URL | AI4: t_2_Detail Images URL | AJ4: t_2_Detail Images URL | AK4: t_2_Detail Images URL | AL4: t_2_Detail Images URL | AM4: t_2_Detail Images URL | AN4: t_2_Detail Images URL | AO4: t_2_Detail Images URL | AP4: t_2_Detail Images URL | AQ4: t_2_Detail Images URL | AR4: t_2_Detail Images URL | AS4: t_2_Detail Images URL | AT4: t_2_Detail Images URL | AU4: t_2_Detail Images URL | AV4: t_2_Detail Images URL | AW4: t_2_Detail Images URL | AX4: t_2_Detail Images URL | AY4: t_2_Detail Images URL | AZ4: t_2_Detail Images URL | BA4: t_2_Detail Images URL | BB4: t_2_Detail Images URL | BC4: t_2_Detail Images URL | BD4: t_2_Detail Images URL | BE4: t_2_Detail Images URL | BF4: t_2_Detail Images URL | BG4: t_2_Detail Images URL | BH4: t_2_Detail Images URL | BI4: t_2_Detail Images URL | BJ4: t_2_Detail Images URL | BK4: t_2_Detail Images URL | BL4: t_2_Detail Images URL | BM4: t_2_Detail Images URL | BN4: t_2_Detail Images URL | BO4: t_2_Detail Images URL | BP4: t_2_Detail Images URL | BQ4: t_2_Detail Images URL | BR4: t_2_Detail Images URL | BS4: t_2_Detail Images URL | BT4: t_2_Detail Images URL | BU4: t_2_Detail Images URL | BV4: t_2_Detail Images URL | BW4: t_2_Detail Images URL | BX4: t_2_Detail Images URL | BY4: t_2_Detail Images URL | BZ4: t_2_Detail Images URL | CA4: t_2_Detail Images URL | CB4: t_2_Detail Images URL | CC4: t_2_Detail Images URL | CD4: t_2_Detail Images URL | CE4: t_2_Detail Images URL | CF4: t_2_Detail Images URL | CG4: t_2_Detail Images URL | CH4: t_2_Detail Images URL | CI4: t_2_Detail Images URL | CJ4: t_2_Detail Images URL | CK4: t_2_Detail Images URL | CL4: t_2_Detail Images URL | CM4: t_2_Detail Images URL | CN4: t_2_Detail Images URL | CO4: t_2_Detail Images URL | CP4: t_2_Detail Images URL | CQ4: t_2_Detail Images URL | CR4: t_2_Detail Images URL | CS4: t_2_Detail Images URL | CT4: t_2_Detail Images URL | CU4: t_2_Detail Images URL | CV4: t_2_Detail Images URL | CW4: t_2_Detail Images URL | CX4: t_2_Detail Images URL | CY4: t_2_Detail Images URL | CZ4: t_2_Detail Images URL | DA4: t_2_Detail Images URL | DB4: t_2_Detail Images URL | DC4: t_2_Detail Images URL | DD4: t_2_Detail Images URL | DE4: t_2_Detail Images URL | DF4: t_2_Detail Images URL | DG4: t_2_Detail Images URL | DH4: t_2_Detail Images URL | DI4: t_2_Detail Images URL | DJ4: t_2_Detail Images URL | DK4: t_2_Detail Images URL | DL4: t_2_Detail Images URL | DM4: t_2_Detail Images URL | DN4: t_2_Detail Images URL | DO4: t_2_Detail Images URL | DP4: t_2_Detail Images URL | DQ4: t_2_Detail Images URL | DR4: t_2_Detail Video URL | DS4: t_3_Property:195 | DT4: t_3_Property:195 | DU4: t_3_Property:4118 | DV4: t_3_Property:4118 | DW4: t_3_Property:4121 | DX4: t_3_Property:4121 | DY4: t_3_Property:4121 | DZ4: t_3_Property:4121 | EA4: t_3_Property:4121 | EB4: t_3_Property:4121 | EC4: t_3_Property:4121 | ED4: t_3_Property:4121 | EE4: t_3_Property:4121 | EF4: t_3_Property:4121 | EG4: t_3_Property:4121 | EH4: t_3_Property:4121 | EI4: t_3_Property:4121 | EJ4: t_3_Property:4121 | EK4: t_3_Property:4121 | EL4: t_3_Property:4121 | EM4: t_3_Property:4121 | EN4: t_3_Property:4121 | EO4: t_3_Property:4121 | EP4: t_3_Property:4121 | EQ4: t_3_Property:4121 | ER4: t_3_Property:4121 | ES4: t_3_Property:4121 | ET4: t_3_Property:4121 | EU4: t_3_Property:4121 | EV4: t_3_Property:4121 | EW4: t_3_Property:4121 | EX4: t_3_Property:4121 | EY4: t_3_Property:4121 | EZ4: t_3_Property:4121 | FA4: t_3_Property:4121 | FB4: t_3_Property:4121 | FC4: t_3_Property:4121 | FD4: t_3_Property:4121 | FE4: t_3_Property:4121 | FF4: t_3_Property:4121 | FG4: t_3_Property:4121 | FH4: t_3_Property:4121 | FI4: t_3_Property:4121 | FJ4: t_3_Property:4121 | FK4: t_3_Property:4121 | FL4: t_3_Property:4121 | FM4: t_3_Property:4121 | FN4: t_3_Property:4121 | FO4: t_3_Property:4121 | FP4: t_3_Property:4121 | FQ4: t_3_Property:4121 | FR4: t_3_Property:4121 | FS4: t_3_Property:4121 | FT4: t_3_Property:4121 | FU4: t_3_Property:4121 | FV4: t_3_Property:4121 | FW4: t_3_Property:4121 | FX4: t_3_Property:4121 | FY4: t_3_Property:4121 | FZ4: t_3_Property:4121 | GA4: t_3_Property:4121 | GB4: t_3_Property:4121 | GC4: t_3_Property:4121 | GD4: t_3_Property:4121 | GE4: t_3_Property:4121 | GF4: t_3_Property:4121 | GG4: t_3_Property:4121 | GH4: t_3_Property:4121 | GI4: t_3_Property:4121 | GJ4: t_3_Property:4121 | GK4: t_3_Property:4121 | GL4: t_3_Property:4121 | GM4: t_3_Property:4121 | GN4: t_3_Property:4121 | GO4: t_3_Property:4121 | GP4: t_3_Property:4121 | GQ4: t_3_Property:4121 | GR4: t_3_Property:4121 | GS4: t_3_Property:4121 | GT4: t_3_Property:4121 | GU4: t_3_Property:4121 | GV4: t_3_Property:4121 | GW4: t_3_Property:4121 | GX4: t_3_Property:4121 | GY4: t_3_Property:4121 | GZ4: t_3_Property:4121 | HA4: t_3_Property:4121 | HB4: t_3_Property:4121 | HC4: t_3_Property:4121 | HD4: t_3_Property:4121 | HE4: t_3_Property:4121 | HF4: t_3_Property:4121 | HG4: t_3_Property:4121 | HH4: t_3_Property:4121 | HI4: t_3_Property:4121 | HJ4: t_3_Property:4121 | HK4: t_3_Property:4121 | HL4: t_3_Property:4121 | HM4: t_3_Property:4121 | HN4: t_3_Property:4121 | HO4: t_3_Property:4121 | HP4: t_3_Property:4121 | HQ4: t_3_Property:4121 | HR4: t_3_Property:4121 | HS4: t_3_Property:6210 | HT4: t_3_Property:6440 | HU4: t_3_Property:4110 | HV4: t_3_Property:4115 - value | HW4: t_3_Property:4115 - unit | HX4: t_3_Property:7413 | HY4: t_3_Property:7414|7413 | HZ4: t_3_Property:7739 | IA4: t_3_Property:7739 | IB4: t_3_Property:7739 | IC4: t_3_Property:7738 | ID4: t_3_Property:7738 | IE4: t_3_Property:7738 | IF4: t_4_Variation Theme | IG4: t_4_Custom Spec:1001 | IH4: t_4_Custom Spec:3001 | II4: t_4_Custom Spec:18012 | IJ4: t_4_Custom Spec:17017 | IK4: t_4_Custom Spec:18013 | IL4: t_4_Custom Spec:17018 | IM4: t_4_Custom Spec:18014 | IN4: t_4_Custom Spec:17019 | IO4: t_4_Custom Spec:18016 | IP4: t_4_Custom Spec:17020 | IQ4: t_4_Custom Spec:15998553 | IR4: t_4_Custom Spec:45114199 | IS4: t_4_Custom Spec:44214483 | IT4: t_6_SKU Images URL | IU4: t_6_SKU Images URL | IV4: t_6_SKU Images URL | IW4: t_6_SKU Images URL | IX4: t_6_SKU Images URL | IY4: t_6_SKU Images URL | IZ4: t_6_SKU Images URL | JA4: t_6_SKU Images URL | JB4: t_6_SKU Images URL | JC4: t_6_SKU Images URL | JD4: t_6_Food Ingredient | JE4: t_6_Quantity | JF4: t_6_Base Price - KRW | JG4: t_6_Reference Link | JH4: t_6_List Price - KRW | JI4: t_6_Weight - g | JJ4: t_6_Length - cm | JK4: t_6_Width - cm | JL4: t_6_Height - cm | JM4: t_6_SKU type | JN4: t_6_Individually packed | JO4: t_6_Total packaging quantity | JP4: t_6_Packaging unit | JQ4: t_6_Total item quantity | JR4: t_6_Item unit | JS4: t_6_Net content | JT4: t_6_Total net content | JU4: t_6_Net content unit | JV4: t_6_External Product ID Type | JW4: t_6_External Product ID | JX4: t_7_Shipping Template | JY4: t_7_Handling Time | JZ4: t_7_Fulfillment Channel | KA4: t_7_Item Tax Code | KB4: t_8_Country/Region of Origin | KC4: t_8_Province of Origin | KD4: t_8_SKU Packaging Information (with visible label) | KE4: t_8_SKU Packaging Information (with visible label) | KF4: t_8_SKU Packaging Information (with visible label) | KG4: t_8_SKU Packaging Information (with visible label) | KH4: t_8_SKU Packaging Information (with visible label) | KI4: t_8_SKU Packaging Information (with visible label) | KJ4: t_8_SKU Packaging Information (with visible label) | KK4: t_8_SKU Packaging Information (with visible label) | KL4: t_8_SKU Packaging Information (with visible label) | KM4: t_8_SKU Packaging Information (with visible label) | KN4: t_8_SKU Packaging Information (with visible label) | KO4: t_8_SKU Packaging Information (with visible label) | KP4: t_8_SKU Packaging Information (with visible label) | KQ4: t_8_SKU Packaging Information (with visible label) | KR4: t_8_SKU Packaging Information (with visible label) | KS4: t_8_SKU Packaging Information (with visible label) | KT4: t_8_SKU Packaging Information (with visible label) | KU4: t_8_SKU Packaging Information (with visible label) | KV4: t_8_SKU Packaging Information (with visible label) | KW4: t_8_SKU Packaging Information (with visible label) | KX4: t_8_SKU Packaging Information (with visible label) | KY4: t_8_SKU Packaging Information (with visible label) | KZ4: t_8_SKU Packaging Information (with visible label) | LA4: t_8_SKU Packaging Information (with visible label) | LB4: t_8_SKU Packaging Information (with visible label) | LC4: t_8_SKU Packaging Information (with visible label) | LD4: t_8_SKU Packaging Information (with visible label) | LE4: t_8_SKU Packaging Information (with visible label) | LF4: t_8_SKU Packaging Information (with visible label) | LG4: t_8_SKU Packaging Information (with visible label) | LH4: t_8_SKU Packaging Information (with visible label) | LI4: t_8_SKU Packaging Information (with visible label) | LJ4: t_8_SKU Packaging Information (with visible label) | LK4: t_8_SKU Packaging Information (with visible label) | LL4: t_8_SKU Packaging Information (with visible label) | LM4: t_8_SKU Packaging Information (with visible label) | LN4: t_8_SKU Packaging Information (with visible label) | LO4: t_8_SKU Packaging Information (with visible label) | LP4: t_8_SKU Packaging Information (with visible label) | LQ4: t_8_SKU Packaging Information (with visible label) | LR4: t_8_SKU Packaging Information (with visible label) | LS4: t_8_SKU Packaging Information (with visible label) | LT4: t_8_SKU Packaging Information (with visible label) | LU4: t_8_SKU Packaging Information (with visible label) | LV4: t_8_SKU Packaging Information (with visible label) | LW4: t_8_Origin Label & Manufacturer Information | LX4: t_8_Origin Label & Manufacturer Information | LY4: t_8_Origin Label & Manufacturer Information | LZ4: t_8_Origin Label & Manufacturer Information | MA4: t_8_Origin Label & Manufacturer Information | MB4: t_8_Product Guide
F5: =IFERROR(VLOOKUP(INDIRECT(ADDRESS(ROW(), COLUMN()-1)), 'Category Name'!$A:$B, 2, FALSE), "먼저 [카테고리]를 선택하십시오. 그러면 카테고리 경로가 표시됩니다. 각 파일에 대해 2000개 이하의 행을 입력하십시오.") -> 0
F6: =IFERROR(VLOOKUP(INDIRECT(ADDRESS(ROW(), COLUMN()-1)), 'Category Name'!$A:$B, 2, FALSE), "먼저 [카테고리]를 선택하십시오. 그러면 카테고리 경로가 표시됩니다. 각 파일에 대해 2000개 이하의 행을 입력하십시오.") -> 0
F7: =IFERROR(VLOOKUP(INDIRECT(ADDRESS(ROW(), COLUMN()-1)), 'Category Name'!$A:$B, 2, FALSE), "먼저 [카테고리]를 선택하십시오. 그러면 카테고리 경로가 표시됩니다. 각 파일에 대해 2000개 이하의 행을 입력하십시오.") -> 0
F8: =IFERROR(VLOOKUP(INDIRECT(ADDRESS(ROW(), COLUMN()-1)), 'Category Name'!$A:$B, 2, FALSE), "먼저 [카테고리]를 선택하십시오. 그러면 카테고리 경로가 표시됩니다. 각 파일에 대해 2000개 이하의 행을 입력하십시오.") -> 0
F9: =IFERROR(VLOOKUP(INDIRECT(ADDRESS(ROW(), COLUMN()-1)), 'Category Name'!$A:$B, 2, FALSE), "먼저 [카테고리]를 선택하십시오. 그러면 카테고리 경로가 표시됩니다. 각 파일에 대해 2000개 이하의 행을 입력하십시오.") -> 0
F10: =IFERROR(VLOOKUP(INDIRECT(ADDRESS(ROW(), COLUMN()-1)), 'Category Name'!$A:$B, 2, FALSE), "먼저 [카테고리]를 선택하십시오. 그러면 카테고리 경로가 표시됩니다. 각 파일에 대해 2000개 이하의 행을 입력하십시오.") -> 0
F11: =IFERROR(VLOOKUP(INDIRECT(ADDRESS(ROW(), COLUMN()-1)), 'Category Name'!$A:$B, 2, FALSE), "먼저 [카테고리]를 선택하십시오. 그러면 카테고리 경로가 표시됩니다. 각 파일에 대해 2000개 이하의 행을 입력하십시오.") -> 0
F12: =IFERROR(VLOOKUP(INDIRECT(ADDRESS(ROW(), COLUMN()-1)), 'Category Name'!$A:$B, 2, FALSE), "먼저 [카테고리]를 선택하십시오. 그러면 카테고리 경로가 표시됩니다. 각 파일에 대해 2000개 이하의 행을 입력하십시오.") -> 0
F13: =IFERROR(VLOOKUP(INDIRECT(ADDRESS(ROW(), COLUMN()-1)), 'Category Name'!$A:$B, 2, FALSE), "먼저 [카테고리]를 선택하십시오. 그러면 카테고리 경로가 표시됩니다. 각 파일에 대해 2000개 이하의 행을 입력하십시오.") -> 0
